Workbook

Sheet 0213
A1: 기획전시 판매현황 | H1: 팀 장
H3: 46066
A4: 1 | B4: 전시명 : | C4: 창작스튜디오 7기 입주작가 프리뷰 | F4: 전시일: | G4: 2026. 2. 13(금) ~ 3. 15(일)
H5: 목표 매출액: | I5: 2080000
B6: 판매현황 | C6: 구분 | D6: 판매매수 | E6: 금액 | F6: 점유율
C7: 유료 | D7: 35 | E7: 70000 | F7: =G10/I5 -> 0.033653846
C8: 무료 | D8: 4
F9: 누계 총인원 | G9: 누계 총 금액 | H9: 누계 무료인원 | I9: 누계 유료인원
C10: 합계 | D10: =SUM(D7:D9) -> 39 | E10: =SUM(E7:E9) -> 70000 | F10: =D10 -> 39 | G10: =E10 -> 70000 | H10: =D8 -> 4 | I10: =D7 -> 35
B11: 비고 | C11: 단체 명 무료 명

Sheet 0214
A1: 기획전시 판매현황 | H1: 팀 장
H3: 46067
A4: 1 | B4: 전시명 : | C4: 창작스튜디오 7기 입주작가 프리뷰 | F4: 전시일: | G4: 2026. 2. 13(금) ~ 3. 15(일)
H5: 목표 매출액: | I5: 2080000
B6: 판매현황 | C6: 구분 | D6: 판매매수 | E6: 금액 | F6: 점유율
C7: 유료 | D7: 50 | E7: 100000 | F7: =G10/I5 -> 0.081730769
C8: 무료 | D8: 0
F9: 누계 총인원 | G9: 누계 총 금액 | H9: 누계 무료인원 | I9: 누계 유료인원
C10: 합계 | D10: =SUM(D7:D9) -> 50 | E10: =SUM(E7:E9) -> 100000 | F10: ='0213'!F10+'0214'!D10 -> 89 | G10: ='0213'!G10+'0214'!E10 -> 170000 | H10: ='0213'!H10+'0214'!D8 -> 4 | I10: ='0213'!I10+'0214'!D7 -> 85
B11: 비고 | C11: 단체 명 무료 명

Sheet 0215
A1: 기획전시 판매현황 | H1: 팀 장
H3: 46068
A4: 1 | B4: 전시명 : | C4: 창작스튜디오 7기 입주작가 프리뷰 | F4: 전시일: | G4: 2026. 2. 13(금) ~ 3. 15(일)
H5: 목표 매출액: | I5: 2080000
B6: 판매현황 | C6: 구분 | D6: 판매매수 | E6: 금액 | F6: 점유율
C7: 유료 | D7: 73 | E7: 146000 | F7: =G10/I5 -> 0.15192308
C8: 무료 | D8: 3
F9: 누계 총인원 | G9: 누계 총 금액 | H9: 누계 무료인원 | I9: 누계 유료인원
C10: 합계 | D10: =SUM(D7:D9) -> 76 | E10: =SUM(E7:E9) -> 146000 | F10: ='0214'!F10+'0215'!D10 -> 165 | G10: ='0214'!G10+'0215'!E10 -> 316000 | H10: ='0214'!H10+'0215'!D8 -> 7 | I10: ='0214'!I10+'0215'!D7 -> 158
B11: 비고 | C11: 단체 명 무료 3명

Sheet 0218
A1: 기획전시 판매현황 | H1: 팀 장
H3: 46071
A4: 1 | B4: 전시명 : | C4: 창작스튜디오 7기 입주작가 프리뷰 | F4: 전시일: | G4: 2026. 2. 13(금) ~ 3. 15(일)
H5: 목표 매출액: | I5: 2080000
B6: 판매현황 | C6: 구분 | D6: 판매매수 | E6: 금액 | F6: 점유율
C7: 유료 | D7: 47 | E7: 94000 | F7: =G10/I5 -> 0.19711538
C8: 무료 | D8: 3
F9: 누계 총인원 | G9: 누계 총 금액 | H9: 누계 무료인원 | I9: 누계 유료인원
C10: 합계 | D10: =SUM(D7:D9) -> 50 | E10: =SUM(E7:E9) -> 94000 | F10: ='0215'!F10+'0218'!D10 -> 215 | G10: ='0215'!G10+'0218'!E10 -> 410000 | H10: ='0215'!H10+'0218'!D8 -> 10 | I10: ='0215'!I10+'0218'!D7 -> 205
B11: 비고 | C11: 단체 명 무료 3명

Sheet 0219
A1: 기획전시 판매현황 | H1: 팀 장
H3: 46072
A4: 1 | B4: 전시명 : | C4: 창작스튜디오 7기 입주작가 프리뷰 | F4: 전시일: | G4: 2026. 2. 13(금) ~ 3. 15(일)
H5: 목표 매출액: | I5: 2080000
B6: 판매현황 | C6: 구분 | D6: 판매매수 | E6: 금액 | F6: 점유율
C7: 유료 | D7: 26 | E7: 52000 | F7: =G10/I5 -> 0.22211538
C8: 무료
F9: 누계 총인원 | G9: 누계 총 금액 | H9: 누계 무료인원 | I9: 누계 유료인원
C10: 합계 | D10: =SUM(D7:D9) -> 26 | E10: =SUM(E7:E9) -> 52000 | F10: ='0218'!F10+'0219'!D10 -> 241 | G10: ='0218'!G10+'0219'!E10 -> 462000 | H10: ='0218'!H10+'0219'!D8 -> 10 | I10: ='0218'!I10+'0219'!D7 -> 231
B11: 비고 | C11: 단체 명 무료 명

Sheet 0220
A1: 기획전시 판매현황 | H1: 팀 장
H3: 46073
A4: 1 | B4: 전시명 : | C4: 창작스튜디오 7기 입주작가 프리뷰 | F4: 전시일: | G4: 2026. 2. 13(금) ~ 3. 15(일)
H5: 목표 매출액: | I5: 2080000
B6: 판매현황 | C6: 구분 | D6: 판매매수 | E6: 금액 | F6: 점유율
C7: 유료 | D7: 25 | E7: 50000 | F7: =G10/I5 -> 0.24615385
C8: 무료 | D8: 0
F9: 누계 총인원 | G9: 누계 총 금액 | H9: 누계 무료인원 | I9: 누계 유료인원
C10: 합계 | D10: =SUM(D7:D9) -> 25 | E10: =SUM(E7:E9) -> 50000 | F10: ='0219'!F10+'0220'!D10 -> 266 | G10: ='0219'!G10+'0220'!E10 -> 512000 | H10: ='0219'!H10+'0220'!D8 -> 10 | I10: ='0219'!I10+'0220'!D7 -> 256
B11: 비고 | C11: 단체 명 무료 명

Sheet 0221
A1: 기획전시 판매현황 | H1: 팀 장
H3: 46074
A4: 1 | B4: 전시명 : | C4: 창작스튜디오 7기 입주작가 프리뷰 | F4: 전시일: | G4: 2026. 2. 13(금) ~ 3. 15(일)
H5: 목표 매출액: | I5: 2080000
B6: 판매현황 | C6: 구분 | D6: 판매매수 | E6: 금액 | F6: 점유율
C7: 유료 | D7: 34 | E7: 68000 | F7: =G10/I5 -> 0.27884615
C8: 무료
F9: 누계 총인원 | G9: 누계 총 금액 | H9: 누계 무료인원 | I9: 누계 유료인원
C10: 합계 | D10: =SUM(D7:D9) -> 34 | E10: =SUM(E7:E9) -> 68000 | F10: ='0220'!F10+'0221'!D10 -> 300 | G10: ='0220'!G10+'0221'!E10 -> 580000 | H10: ='0220'!H10+'0221'!D8 -> 10 | I10: ='0220'!I10+'0221'!D7 -> 290
B11: 비고 | C11: 단체 명 무료 명

Sheet 0222
A1: 기획전시 판매현황 | H1: 팀 장
H3: 46075
A4: 1 | B4: 전시명 : | C4: 창작스튜디오 7기 입주작가 프리뷰 | F4: 전시일: | G4: 2026. 2. 13(금) ~ 3. 15(일)
H5: 목표 매출액: | I5: 2080000
B6: 판매현황 | C6: 구분 | D6: 판매매수 | E6: 금액 | F6: 점유율
C7: 유료 | D7: 24 | E7: 48000 | F7: =G10/I5 -> 0.30192308
C8: 무료
F9: 누계 총인원 | G9: 누계 총 금액 | H9: 누계 무료인원 | I9: 누계 유료인원
C10: 합계 | D10: =SUM(D7:D9) -> 24 | E10: =SUM(E7:E9) -> 48000 | F10: ='0221'!F10+'0222'!D10 -> 324 | G10: ='0221'!G10+'0222'!E10 -> 628000 | H10: ='0221'!H10+'0222'!D8 -> 10 | I10: ='0221'!I10+'0222'!D7 -> 314
B11: 비고 | C11: 단체 명 무료 명

Sheet 0224
A1: 기획전시 판매현황 | H1: 팀 장
H3: 46077
A4: 1 | B4: 전시명 : | C4: 창작스튜디오 7기 입주작가 프리뷰 | F4: 전시일: | G4: 2026. 2. 13(금) ~ 3. 15(일)
H5: 목표 매출액: | I5: 2080000
B6: 판매현황 | C6: 구분 | D6: 판매매수 | E6: 금액 | F6: 점유율
C7: 유료 | D7: 8 | E7: 16000 | F7: =G10/I5 -> 0.30961538
C8: 무료
F9: 누계 총인원 | G9: 누계 총 금액 | H9: 누계 무료인원 | I9: 누계 유료인원
C10: 합계 | D10: =SUM(D7:D9) -> 8 | E10: =SUM(E7:E9) -> 16000 | F10: ='0222'!F10+'0224'!D10 -> 332 | G10: ='0222'!G10+'0224'!E10 -> 644000 | H10: ='0222'!H10+'0224'!D8 -> 10 | I10: ='0222'!I10+'0224'!D7 -> 322
B11: 비고 | C11: 단체 명 무료 명
I19: .

Sheet 0225
A1: 기획전시 판매현황 | H1: 팀 장
H3: 46078
A4: 1 | B4: 전시명 : | C4: 창작스튜디오 7기 입주작가 프리뷰 | F4: 전시일: | G4: 2026. 2. 13(금) ~ 3. 15(일)
H5: 목표 매출액: | I5: 2080000
B6: 판매현황 | C6: 구분 | D6: 판매매수 | E6: 금액 | F6: 점유율
C7: 유료 | D7: 31 | E7: 62000 | F7: =G10/I5 -> 0.33942308
C8: 무료 | D8: 3
F9: 누계 총인원 | G9: 누계 총 금액 | H9: 누계 무료인원 | I9: 누계 유료인원
C10: 합계 | D10: =SUM(D7:D9) -> 34 | E10: =SUM(E7:E9) -> 62000 | F10: ='0224'!F10+'0225'!D10 -> 366 | G10: ='0224'!G10+'0225'!E10 -> 706000 | H10: ='0224'!H10+'0225'!D8 -> 13 | I10: ='0224'!I10+'0225'!D7 -> 353
B11: 비고 | C11: 단체 명 무료 3명
I19: .

Sheet 0226
A1: 기획전시 판매현황 | H1: 팀 장
H3: 46079
A4: 1 | B4: 전시명 : | C4: 창작스튜디오 7기 입주작가 프리뷰 | F4: 전시일: | G4: 2026. 2. 13(금) ~ 3. 15(일)
H5: 목표 매출액: | I5: 2080000
B6: 판매현황 | C6: 구분 | D6: 판매매수 | E6: 금액 | F6: 점유율
C7: 유료 | D7: 22 | E7: 44000 | F7: =G10/I5 -> 0.36057692
C8: 무료 | D8: 5
F9: 누계 총인원 | G9: 누계 총 금액 | H9: 누계 무료인원 | I9: 누계 유료인원
C10: 합계 | D10: =SUM(D7:D9) -> 27 | E10: =SUM(E7:E9) -> 44000 | F10: ='0225'!F10+'0226'!D10 -> 393 | G10: ='0225'!G10+'0226'!E10 -> 750000 | H10: ='0225'!H10+'0226'!D8 -> 18 | I10: ='0225'!I10+'0226'!D7 -> 375
B11: 비고 | C11: 단체 명 무료 5명
I19: .

Sheet 0227
A1: 기획전시 판매현황 | H1: 팀 장
H3: 46080
A4: 1 | B4: 전시명 : | C4: 창작스튜디오 7기 입주작가 프리뷰 | F4: 전시일: | G4: 2026. 2. 13(금) ~ 3. 15(일)
H5: 목표 매출액: | I5: 2080000
B6: 판매현황 | C6: 구분 | D6: 판매매수 | E6: 금액 | F6: 점유율
C7: 유료 | D7: 22 | E7: 44000 | F7: =G10/I5 -> 0.38173077
C8: 무료 | D8: 0
F9: 누계 총인원 | G9: 누계 총 금액 | H9: 누계 무료인원 | I9: 누계 유료인원
C10: 합계 | D10: =SUM(D7:D9) -> 22 | E10: =SUM(E7:E9) -> 44000 | F10: ='0226'!F10+'0227'!D10 -> 415 | G10: ='0226'!G10+'0227'!E10 -> 794000 | H10: ='0226'!H10+'0227'!D8 -> 18 | I10: ='0226'!I10+'0227'!D7 -> 397
B11: 비고 | C11: 단체 명 무료 명
A12: 2 | B12: 전시명 : | C12: 어린이미술전 <우리 SUM 타볼래> | F12: 전시일: | G12: 2026. 2. 27(금) ~ 6. 28(일)
H13: 목표 매출액: | I13: 31500000
B14: 판매현황 | C14: 구분 | D14: 판매매수 | E14: 금액 | F14: 점유율
C15: 유료 | D15: 5 | E15: 29000 | F15: =G18/I13 -> 0.00092063492
C16: 무료 | D16: 0
F17: 누계 총인원 | G17: 누계 총 금액 | H17: 누계 무료인원 | I17: 누계 유료인원
C18: 합계 | D18: =SUM(D15:D17) -> 5 | E18: =SUM(E15:E17) -> 29000 | F18: ='0227'!D18 -> 5 | G18: ='0227'!E18 -> 29000 | H18: ='0227'!D16 -> 0 | I18: ='0227'!D15 -> 5
B19: 비고 | C19: 단체 명 무료 명

Sheet 0228
A1: 기획전시 판매현황 | H1: 팀 장
H3: 46081
A4: 1 | B4: 전시명 : | C4: 창작스튜디오 7기 입주작가 프리뷰 | F4: 전시일: | G4: 2026. 2. 13(금) ~ 3. 15(일)
H5: 목표 매출액: | I5: 2080000
B6: 판매현황 | C6: 구분 | D6: 판매매수 | E6: 금액 | F6: 점유율
C7: 유료 | D7: 33 | E7: 66000 | F7: =G10/I5 -> 0.41346154
C8: 무료 | D8: 3
F9: 누계 총인원 | G9: 누계 총 금액 | H9: 누계 무료인원 | I9: 누계 유료인원
C10: 합계 | D10: =SUM(D7:D9) -> 36 | E10: =SUM(E7:E9) -> 66000 | F10: ='0227'!F10+'0228'!D10 -> 451 | G10: ='0227'!G10+'0228'!E10 -> 860000 | H10: ='0227'!H10+'0228'!D8 -> 21 | I10: ='0227'!I10+'0228'!D7 -> 430
B11: 비고 | C11: 단체 명 무료 3명
A12: 2 | B12: 전시명 : | C12: 어린이미술전 <우리 SUM 타볼래> | F12: 전시일: | G12: 2026. 2. 27(금) ~ 6. 28(일)
H13: 목표 매출액: | I13: 31500000
B14: 판매현황 | C14: 구분 | D14: 판매매수 | E14: 금액 | F14: 점유율
C15: 유료 | D15: 33 | E15: 199000 | F15: =G18/I13 -> 0.0072380952
C16: 무료 | D16: 1
F17: 누계 총인원 | G17: 누계 총 금액 | H17: 누계 무료인원 | I17: 누계 유료인원
C18: 합계 | D18: =SUM(D15:D17) -> 34 | E18: =SUM(E15:E17) -> 199000 | F18: ='0227'!F18+'0228'!D18 -> 39 | G18: ='0227'!G18+'0228'!E18 -> 228000 | H18: ='0227'!H18+'0228'!D16 -> 1 | I18: ='0227'!I18+'0228'!D15 -> 38
B19: 비고 | C19: 단체 명 무료 1명

Sheet 0301
A1: 기획전시 판매현황 | H1: 팀 장
H3: 46082
A4: 1 | B4: 전시명 : | C4: 창작스튜디오 7기 입주작가 프리뷰 | F4: 전시일: | G4: 2026. 2. 13(금) ~ 3. 15(일)
H5: 목표 매출액: | I5: 2080000
B6: 판매현황 | C6: 구분 | D6: 판매매수 | E6: 금액 | F6: 점유율
C7: 유료 | D7: 51 | E7: 102000 | F7: =G10/I5 -> 0.4625
C8: 무료 | D8: 1
F9: 누계 총인원 | G9: 누계 총 금액 | H9: 누계 무료인원 | I9: 누계 유료인원
C10: 합계 | D10: =SUM(D7:D9) -> 52 | E10: =SUM(E7:E9) -> 102000 | F10: ='0228'!F10+'0301'!D10 -> 503 | G10: ='0228'!G10+'0301'!E10 -> 962000 | H10: ='0228'!H10+'0301'!D8 -> 22 | I10: ='0228'!I10+'0301'!D7 -> 481
B11: 비고 | C11: 단체 명 무료 1명
A12: 2 | B12: 전시명 : | C12: 어린이미술전 <우리 SUM 타볼래> | F12: 전시일: | G12: 2026. 2. 27(금) ~ 6. 28(일)
H13: 목표 매출액: | I13: 31500000
B14: 판매현황 | C14: 구분 | D14: 판매매수 | E14: 금액 | F14: 점유율
C15: 유료 | D15: 42 | E15: 254000 | F15: =G18/I13 -> 0.015301587
C16: 무료 | D16: 3
F17: 누계 총인원 | G17: 누계 총 금액 | H17: 누계 무료인원 | I17: 누계 유료인원
C18: 합계 | D18: =SUM(D15:D17) -> 45 | E18: =SUM(E15:E17) -> 254000 | F18: ='0228'!F18+'0301'!D18 -> 84 | G18: ='0228'!G18+'0301'!E18 -> 482000 | H18: ='0228'!H18+'0301'!D16 -> 4 | I18: ='0228'!I18+'0301'!D15 -> 80
B19: 비고 | C19: 단체 명 무료 3명

Sheet 0303
A1: 기획전시 판매현황 | H1: 팀 장
H3: 46084
A4: 1 | B4: 전시명 : | C4: 창작스튜디오 7기 입주작가 프리뷰 | F4: 전시일: | G4: 2026. 2. 13(금) ~ 3. 15(일)
H5: 목표 매출액: | I5: 2080000
B6: 판매현황 | C6: 구분 | D6: 판매매수 | E6: 금액 | F6: 점유율
C7: 유료 | D7: 10 | E7: 20000 | F7: =G10/I5 -> 0.47211538
C8: 무료 | D8: 0
F9: 누계 총인원 | G9: 누계 총 금액 | H9: 누계 무료인원 | I9: 누계 유료인원
C10: 합계 | D10: =SUM(D7:D9) -> 10 | E10: =SUM(E7:E9) -> 20000 | F10: ='0301'!F10+'0303'!D10 -> 513 | G10: ='0301'!G10+'0303'!E10 -> 982000 | H10: ='0301'!H10+'0303'!D8 -> 22 | I10: ='0301'!I10+'0303'!D7 -> 491
B11: 비고 | C11: 단체 명 무료 명
A12: 2 | B12: 전시명 : | C12: 어린이미술전 <우리 SUM 타볼래> | F12: 전시일: | G12: 2026. 2. 27(금) ~ 6. 28(일)
H13: 목표 매출액: | I13: 31500000
B14: 판매현황 | C14: 구분 | D14: 판매매수 | E14: 금액 | F14: 점유율
C15: 유료 | D15: 4 | E15: 22000 | F15: =G18/I13 -> 0.016
C16: 무료 | D16: 1
F17: 누계 총인원 | G17: 누계 총 금액 | H17: 누계 무료인원 | I17: 누계 유료인원
C18: 합계 | D18: =SUM(D15:D17) -> 5 | E18: =SUM(E15:E17) -> 22000 | F18: ='0301'!F18+'0303'!D18 -> 89 | G18: ='0301'!G18+'0303'!E18 -> 504000 | H18: ='0301'!H18+'0303'!D16 -> 5 | I18: ='0301'!I18+'0303'!D15 -> 84
B19: 비고 | C19: 단체 명 무료 1명

Sheet 0304
A1: 기획전시 판매현황 | H1: 팀 장
H3: 46085
A4: 1 | B4: 전시명 : | C4: 창작스튜디오 7기 입주작가 프리뷰 | F4: 전시일: | G4: 2026. 2. 13(금) ~ 3. 15(일)
H5: 목표 매출액: | I5: 2080000
B6: 판매현황 | C6: 구분 | D6: 판매매수 | E6: 금액 | F6: 점유율
C7: 유료 | D7: 14 | E7: 28000 | F7: =G10/I5 -> 0.48557692
C8: 무료 | D8: 2
F9: 누계 총인원 | G9: 누계 총 금액 | H9: 누계 무료인원 | I9: 누계 유료인원
C10: 합계 | D10: =SUM(D7:D9) -> 16 | E10: =SUM(E7:E9) -> 28000 | F10: ='0303'!F10+'0304'!D10 -> 529 | G10: ='0303'!G10+'0304'!E10 -> 1010000 | H10: ='0303'!H10+'0304'!D8 -> 24 | I10: ='0303'!I10+'0304'!D7 -> 505
B11: 비고 | C11: 단체 명 무료 2명
A12: 2 | B12: 전시명 : | C12: 어린이미술전 <우리 SUM 타볼래> | F12: 전시일: | G12: 2026. 2. 27(금) ~ 6. 28(일)
H13: 목표 매출액: | I13: 31500000
B14: 판매현황 | C14: 구분 | D14: 판매매수 | E14: 금액 | F14: 점유율
C15: 유료 | D15: 6 | E15: 36000 | F15: =G18/I13 -> 0.017142857
C16: 무료 | D16: 0
F17: 누계 총인원 | G17: 누계 총 금액 | H17: 누계 무료인원 | I17: 누계 유료인원
C18: 합계 | D18: =SUM(D15:D17) -> 6 | E18: =SUM(E15:E17) -> 36000 | F18: ='0303'!F18+'0304'!D18 -> 95 | G18: ='0303'!G18+'0304'!E18 -> 540000 | H18: ='0303'!H18+'0304'!D16 -> 5 | I18: ='0303'!I18+'0304'!D15 -> 90
B19: 비고 | C19: 단체 명 무료 명 | F19: 현금결제 1건 취소로 유료 6매, 36,000원임 정산리포트와 상이함(유료 7매, 41,000원)

Sheet 0305
A1: 기획전시 판매현황 | H1: 팀 장
H3: 46086
A4: 1 | B4: 전시명 : | C4: 창작스튜디오 7기 입주작가 프리뷰 | F4: 전시일: | G4: 2026. 2. 13(금) ~ 3. 15(일)
H5: 목표 매출액: | I5: 2080000
B6: 판매현황 | C6: 구분 | D6: 판매매수 | E6: 금액 | F6: 점유율
C7: 유료 | D7: 11 | E7: 22000 | F7: =G10/I5 -> 0.49615385
C8: 무료 | D8: 0
F9: 누계 총인원 | G9: 누계 총 금액 | H9: 누계 무료인원 | I9: 누계 유료인원
C10: 합계 | D10: =SUM(D7:D9) -> 11 | E10: =SUM(E7:E9) -> 22000 | F10: ='0304'!F10+'0305'!D10 -> 540 | G10: ='0304'!G10+'0305'!E10 -> 1032000 | H10: ='0304'!H10+'0305'!D8 -> 24 | I10: ='0304'!I10+'0305'!D7 -> 516
B11: 비고 | C11: 단체 명 무료 명
A12: 2 | B12: 전시명 : | C12: 어린이미술전 <우리 SUM 타볼래> | F12: 전시일: | G12: 2026. 2. 27(금) ~ 6. 28(일)
H13: 목표 매출액: | I13: 31500000
B14: 판매현황 | C14: 구분 | D14: 판매매수 | E14: 금액 | F14: 점유율
C15: 유료 | D15: 2 | E15: 12000 | F15: =G18/I13 -> 0.01752381
C16: 무료 | D16: 0
F17: 누계 총인원 | G17: 누계 총 금액 | H17: 누계 무료인원 | I17: 누계 유료인원
C18: 합계 | D18: =SUM(D15:D17) -> 2 | E18: =SUM(E15:E17) -> 12000 | F18: ='0304'!F18+'0305'!D18 -> 97 | G18: ='0304'!G18+'0305'!E18 -> 552000 | H18: ='0304'!H18+'0305'!D16 -> 5 | I18: ='0304'!I18+'0305'!D15 -> 92
B19: 비고 | C19: 단체 명 무료 명

Sheet 0306
A1: 기획전시 판매현황 | H1: 팀 장
H3: 46087
A4: 1 | B4: 전시명 : | C4: 창작스튜디오 7기 입주작가 프리뷰 | F4: 전시일: | G4: 2026. 2. 13(금) ~ 3. 15(일)
H5: 목표 매출액: | I5: 2080000
B6: 판매현황 | C6: 구분 | D6: 판매매수 | E6: 금액 | F6: 점유율
C7: 유료 | D7: 4 | E7: 8000 | F7: =G10/I5 -> 0.5
C8: 무료 | D8: 0
F9: 누계 총인원 | G9: 누계 총 금액 | H9: 누계 무료인원 | I9: 누계 유료인원
C10: 합계 | D10: =SUM(D7:D9) -> 4 | E10: =SUM(E7:E9) -> 8000 | F10: ='0305'!F10+'0306'!D10 -> 544 | G10: ='0305'!G10+'0306'!E10 -> 1040000 | H10: ='0305'!H10+'0306'!D8 -> 24 | I10: ='0305'!I10+'0306'!D7 -> 520
B11: 비고 | C11: 단체 명 무료 명
A12: 2 | B12: 전시명 : | C12: 어린이미술전 <우리 SUM 타볼래> | F12: 전시일: | G12: 2026. 2. 27(금) ~ 6. 28(일)
H13: 목표 매출액: | I13: 31500000
B14: 판매현황 | C14: 구분 | D14: 판매매수 | E14: 금액 | F14: 점유율
C15: 유료 | D15: 12 | E15: 64000 | F15: =G18/I13 -> 0.019555556
C16: 무료 | D16: 1
F17: 누계 총인원 | G17: 누계 총 금액 | H17: 누계 무료인원 | I17: 누계 유료인원
C18: 합계 | D18: =SUM(D15:D17) -> 13 | E18: =SUM(E15:E17) -> 64000 | F18: ='0305'!F18+'0306'!D18 -> 110 | G18: ='0305'!G18+'0306'!E18 -> 616000 | H18: ='0305'!H18+'0306'!D16 -> 6 | I18: ='0305'!I18+'0306'!D15 -> 104
B19: 비고 | C19: 단체 명 무료 1명

Sheet 0307
A1: 기획전시 판매현황 | H1: 팀 장
H3: 46088
A4: 1 | B4: 전시명 : | C4: 창작스튜디오 7기 입주작가 프리뷰 | F4: 전시일: | G4: 2026. 2. 13(금) ~ 3. 22(일)
H5: 목표 매출액: | I5: 2080000
B6: 판매현황 | C6: 구분 | D6: 판매매수 | E6: 금액 | F6: 점유율
C7: 유료 | D7: 39 | E7: 78000 | F7: =G10/I5 -> 0.5375
C8: 무료 | D8: 2
F9: 누계 총인원 | G9: 누계 총 금액 | H9: 누계 무료인원 | I9: 누계 유료인원
C10: 합계 | D10: =SUM(D7:D9) -> 41 | E10: =SUM(E7:E9) -> 78000 | F10: ='0306'!F10+'0307'!D10 -> 585 | G10: ='0306'!G10+'0307'!E10 -> 1118000 | H10: ='0306'!H10+'0307'!D8 -> 26 | I10: ='0306'!I10+'0307'!D7 -> 559
B11: 비고 | C11: 단체 명 무료 2명
A12: 2 | B12: 전시명 : | C12: 어린이미술전 <우리 SUM 타볼래> | F12: 전시일: | G12: 2026. 2. 27(금) ~ 6. 28(일)
H13: 목표 매출액: | I13: 31500000
B14: 판매현황 | C14: 구분 | D14: 판매매수 | E14: 금액 | F14: 점유율
C15: 유료 | D15: 21 | E15: 125000 | F15: =G18/I13 -> 0.02352381
C16: 무료 | D16: 4
F17: 누계 총인원 | G17: 누계 총 금액 | H17: 누계 무료인원 | I17: 누계 유료인원
C18: 합계 | D18: =SUM(D15:D17) -> 25 | E18: =SUM(E15:E17) -> 125000 | F18: ='0306'!F18+'0307'!D18 -> 135 | G18: ='0306'!G18+'0307'!E18 -> 741000 | H18: ='0306'!H18+'0307'!D16 -> 10 | I18: ='0306'!I18+'0307'!D15 -> 125
B19: 비고 | C19: 단체 명 무료 4명

Sheet 0308
A1: 기획전시 판매현황 | H1: 팀 장
H3: 46089
A4: 1 | B4: 전시명 : | C4: 창작스튜디오 7기 입주작가 프리뷰 | F4: 전시일: | G4: 2026. 2. 13(금) ~ 3. 22(일)
H5: 목표 매출액: | I5: 2080000
B6: 판매현황 | C6: 구분 | D6: 판매매수 | E6: 금액 | F6: 점유율
C7: 유료 | D7: 27 | E7: 54000 | F7: =G10/I5 -> 0.56346154
C8: 무료 | D8: 5
F9: 누계 총인원 | G9: 누계 총 금액 | H9: 누계 무료인원 | I9: 누계 유료인원
C10: 합계 | D10: =SUM(D7:D9) -> 32 | E10: =SUM(E7:E9) -> 54000 | F10: ='0307'!F10+'0308'!D10 -> 617 | G10: ='0307'!G10+'0308'!E10 -> 1172000 | H10: ='0307'!H10+'0308'!D8 -> 31 | I10: ='0307'!I10+'0308'!D7 -> 586
B11: 비고 | C11: 단체 명 무료 5명
A12: 2 | B12: 전시명 : | C12: 어린이미술전 <우리 SUM 타볼래> | F12: 전시일: | G12: 2026. 2. 27(금) ~ 6. 28(일)
H13: 목표 매출액: | I13: 31500000
B14: 판매현황 | C14: 구분 | D14: 판매매수 | E14: 금액 | F14: 점유율
C15: 유료 | D15: 44 | E15: 262000 | F15: =G18/I13 -> 0.03184127
C16: 무료 | D16: 2
F17: 누계 총인원 | G17: 누계 총 금액 | H17: 누계 무료인원 | I17: 누계 유료인원
C18: 합계 | D18: =SUM(D15:D17) -> 46 | E18: =SUM(E15:E17) -> 262000 | F18: ='0307'!F18+'0308'!D18 -> 181 | G18: ='0307'!G18+'0308'!E18 -> 1003000 | H18: ='0307'!H18+'0308'!D16 -> 12 | I18: ='0307'!I18+'0308'!D15 -> 169
B19: 비고 | C19: 단체 명 무료 2명

Sheet 0310
A1: 기획전시 판매현황 | H1: 팀 장
H3: 46091
A4: 1 | B4: 전시명 : | C4: 창작스튜디오 7기 입주작가 프리뷰 | F4: 전시일: | G4: 2026. 2. 13(금) ~ 3. 22(일)
H5: 목표 매출액: | I5: 2080000
B6: 판매현황 | C6: 구분 | D6: 판매매수 | E6: 금액 | F6: 점유율
C7: 유료 | D7: 10 | E7: 20000 | F7: =G10/I5 -> 0.57307692
C8: 무료 | D8: 7
F9: 누계 총인원 | G9: 누계 총 금액 | H9: 누계 무료인원 | I9: 누계 유료인원
C10: 합계 | D10: =SUM(D7:D9) -> 17 | E10: =SUM(E7:E9) -> 20000 | F10: ='0308'!F10+'0310'!D10 -> 634 | G10: ='0308'!G10+'0310'!E10 -> 1192000 | H10: ='0308'!H10+'0310'!D8 -> 38 | I10: ='0308'!I10+'0310'!D7 -> 596
B11: 비고 | C11: 단체 명 무료 7명
A12: 2 | B12: 전시명 : | C12: 어린이미술전 <우리 SUM 타볼래> | F12: 전시일: | G12: 2026. 2. 27(금) ~ 6. 28(일)
H13: 목표 매출액: | I13: 31500000
B14: 판매현황 | C14: 구분 | D14: 판매매수 | E14: 금액 | F14: 점유율
C15: 유료 | D15: 6 | E15: 36000 | F15: =G18/I13 -> 0.032984127
C16: 무료 | D16: 1
F17: 누계 총인원 | G17: 누계 총 금액 | H17: 누계 무료인원 | I17: 누계 유료인원
C18: 합계 | D18: =SUM(D15:D17) -> 7 | E18: =SUM(E15:E17) -> 36000 | F18: ='0308'!F18+'0310'!D18 -> 188 | G18: ='0308'!G18+'0310'!E18 -> 1039000 | H18: ='0308'!H18+'0310'!D16 -> 13 | I18: ='0308'!I18+'0310'!D15 -> 175
B19: 비고 | C19: 단체 명 무료 1명

Sheet 0311
A1: 기획전시 판매현황 | H1: 팀 장
H3: 46092
A4: 1 | B4: 전시명 : | C4: 창작스튜디오 7기 입주작가 프리뷰 | F4: 전시일: | G4: 2026. 2. 13(금) ~ 3. 22(일)
H5: 목표 매출액: | I5: 2080000
B6: 판매현황 | C6: 구분 | D6: 판매매수 | E6: 금액 | F6: 점유율
C7: 유료 | D7: 12 | E7: 24000 | F7: =G10/I5 -> 0.58461538
C8: 무료 | D8: 2
F9: 누계 총인원 | G9: 누계 총 금액 | H9: 누계 무료인원 | I9: 누계 유료인원
C10: 합계 | D10: =SUM(D7:D9) -> 14 | E10: =SUM(E7:E9) -> 24000 | F10: ='0310'!F10+'0311'!D10 -> 648 | G10: ='0310'!G10+'0311'!E10 -> 1216000 | H10: ='0310'!H10+'0311'!D8 -> 40 | I10: ='0310'!I10+'0311'!D7 -> 608
B11: 비고 | C11: 단체 명 무료 2명
A12: 2 | B12: 전시명 : | C12: 어린이미술전 <우리 SUM 타볼래> | F12: 전시일: | G12: 2026. 2. 27(금) ~ 6. 28(일)
H13: 목표 매출액: | I13: 31500000
B14: 판매현황 | C14: 구분 | D14: 판매매수 | E14: 금액 | F14: 점유율
C15: 유료 | D15: 4 | E15: 22000 | F15: =G18/I13 -> 0.03368254
C16: 무료 | D16: 1
F17: 누계 총인원 | G17: 누계 총 금액 | H17: 누계 무료인원 | I17: 누계 유료인원
C18: 합계 | D18: =SUM(D15:D17) -> 5 | E18: =SUM(E15:E17) -> 22000 | F18: ='0310'!F18+'0311'!D18 -> 193 | G18: ='0310'!G18+'0311'!E18 -> 1061000 | H18: ='0310'!H18+'0311'!D16 -> 14 | I18: ='0310'!I18+'0311'!D15 -> 179
B19: 비고 | C19: 단체 명 무료 1명

Sheet 0312
A1: 기획전시 판매현황 | H1: 팀 장
H3: 46093
A4: 1 | B4: 전시명 : | C4: 창작스튜디오 7기 입주작가 프리뷰 | F4: 전시일: | G4: 2026. 2. 13(금) ~ 3. 22(일)
H5: 목표 매출액: | I5: 2080000
B6: 판매현황 | C6: 구분 | D6: 판매매수 | E6: 금액 | F6: 점유율
C7: 유료 | D7: 28 | E7: 56000 | F7: =G10/I5 -> 0.61153846
C8: 무료 | D8: 2
F9: 누계 총인원 | G9: 누계 총 금액 | H9: 누계 무료인원 | I9: 누계 유료인원
C10: 합계 | D10: =SUM(D7:D9) -> 30 | E10: =SUM(E7:E9) -> 56000 | F10: ='0311'!F10+'0312'!D10 -> 678 | G10: ='0311'!G10+'0312'!E10 -> 1272000 | H10: ='0311'!H10+'0312'!D8 -> 42 | I10: ='0311'!I10+'0312'!D7 -> 636
B11: 비고 | C11: 단체 명 무료 2명
A12: 2 | B12: 전시명 : | C12: 어린이미술전 <우리 SUM 타볼래> | F12: 전시일: | G12: 2026. 2. 27(금) ~ 6. 28(일)
H13: 목표 매출액: | I13: 31500000
B14: 판매현황 | C14: 구분 | D14: 판매매수 | E14: 금액 | F14: 점유율
C15: 유료 | D15: 2 | E15: 10000 | F15: =G18/I13 -> 0.034
C16: 무료 | D16: 1
F17: 누계 총인원 | G17: 누계 총 금액 | H17: 누계 무료인원 | I17: 누계 유료인원
C18: 합계 | D18: =SUM(D15:D17) -> 3 | E18: =SUM(E15:E17) -> 10000 | F18: ='0311'!F18+'0312'!D18 -> 196 | G18: ='0311'!G18+'0312'!E18 -> 1071000 | H18: ='0311'!H18+'0312'!D16 -> 15 | I18: ='0311'!I18+'0312'!D15 -> 181
B19: 비고 | C19: 단체 명 무료 1명

Sheet 0313
A1: 기획전시 판매현황 | H1: 팀 장
H3: 46094
A4: 1 | B4: 전시명 : | C4: 창작스튜디오 7기 입주작가 프리뷰 | F4: 전시일: | G4: 2026. 2. 13(금) ~ 3. 22(일)
H5: 목표 매출액: | I5: 2080000
B6: 판매현황 | C6: 구분 | D6: 판매매수 | E6: 금액 | F6: 점유율
C7: 유료 | D7: 11 | E7: 22000 | F7: =G10/I5 -> 0.62211538
C8: 무료 | D8: 0
F9: 누계 총인원 | G9: 누계 총 금액 | H9: 누계 무료인원 | I9: 누계 유료인원
C10: 합계 | D10: =SUM(D7:D9) -> 11 | E10: =SUM(E7:E9) -> 22000 | F10: ='0312'!F10+'0313'!D10 -> 689 | G10: ='0312'!G10+'0313'!E10 -> 1294000 | H10: ='0312'!H10+'0313'!D8 -> 42 | I10: ='0312'!I10+'0313'!D7 -> 647
B11: 비고 | C11: 단체 명 무료 명
A12: 2 | B12: 전시명 : | C12: 어린이미술전 <우리 SUM 타볼래> | F12: 전시일: | G12: 2026. 2. 27(금) ~ 6. 28(일)
H13: 목표 매출액: | I13: 31500000
B14: 판매현황 | C14: 구분 | D14: 판매매수 | E14: 금액 | F14: 점유율
C15: 유료 | D15: 66 | E15: 298500 | F15: =G18/I13 -> 0.04347619
C16: 무료 | D16: 0
F17: 누계 총인원 | G17: 누계 총 금액 | H17: 누계 무료인원 | I17: 누계 유료인원
C18: 합계 | D18: =SUM(D15:D17) -> 66 | E18: =SUM(E15:E17) -> 298500 | F18: ='0312'!F18+'0313'!D18 -> 262 | G18: ='0312'!G18+'0313'!E18 -> 1369500 | H18: ='0312'!H18+'0313'!D16 -> 15 | I18: ='0312'!I18+'0313'!D15 -> 247
B19: 비고 | C19: 단체 63명 무료 명

Sheet 0314
A1: 기획전시 판매현황 | H1: 팀 장
H3: 46095
A4: 1 | B4: 전시명 : | C4: 창작스튜디오 7기 입주작가 프리뷰 | F4: 전시일: | G4: 2026. 2. 13(금) ~ 3. 22(일)
H5: 목표 매출액: | I5: 2080000
B6: 판매현황 | C6: 구분 | D6: 판매매수 | E6: 금액 | F6: 점유율
C7: 유료 | D7: 44 | E7: 88000 | F7: =G10/I5 -> 0.66442308
C8: 무료 | D8: 0
F9: 누계 총인원 | G9: 누계 총 금액 | H9: 누계 무료인원 | I9: 누계 유료인원
C10: 합계 | D10: =SUM(D7:D9) -> 44 | E10: =SUM(E7:E9) -> 88000 | F10: ='0313'!F10+'0314'!D10 -> 733 | G10: ='0313'!G10+'0314'!E10 -> 1382000 | H10: ='0313'!H10+'0314'!D8 -> 42 | I10: ='0313'!I10+'0314'!D7 -> 691
B11: 비고 | C11: 단체 명 무료 명
A12: 2 | B12: 전시명 : | C12: 어린이미술전 <우리 SUM 타볼래> | F12: 전시일: | G12: 2026. 2. 27(금) ~ 6. 28(일)
H13: 목표 매출액: | I13: 31500000
B14: 판매현황 | C14: 구분 | D14: 판매매수 | E14: 금액 | F14: 점유율
C15: 유료 | D15: 72 | E15: 414000 | F15: =G18/I13 -> 0.056619048
C16: 무료 | D16: 3
F17: 누계 총인원 | G17: 누계 총 금액 | H17: 누계 무료인원 | I17: 누계 유료인원
C18: 합계 | D18: =SUM(D15:D17) -> 75 | E18: =SUM(E15:E17) -> 414000 | F18: ='0313'!F18+'0314'!D18 -> 337 | G18: ='0313'!G18+'0314'!E18 -> 1783500 | H18: ='0313'!H18+'0314'!D16 -> 18 | I18: ='0313'!I18+'0314'!D15 -> 319
B19: 비고 | C19: 단체 명 무료 3명

Sheet 0315
A1: 기획전시 판매현황 | H1: 팀 장
H3: 46096
A4: 1 | B4: 전시명 : | C4: 창작스튜디오 7기 입주작가 프리뷰 | F4: 전시일: | G4: 2026. 2. 13(금) ~ 3. 22(일)
H5: 목표 매출액: | I5: 2080000
B6: 판매현황 | C6: 구분 | D6: 판매매수 | E6: 금액 | F6: 점유율
C7: 유료 | D7: 45 | E7: 90000 | F7: =G10/I5 -> 0.70769231
C8: 무료 | D8: 0
F9: 누계 총인원 | G9: 누계 총 금액 | H9: 누계 무료인원 | I9: 누계 유료인원
C10: 합계 | D10: =SUM(D7:D9) -> 45 | E10: =SUM(E7:E9) -> 90000 | F10: ='0314'!F10+'0315'!D10 -> 778 | G10: ='0314'!G10+'0315'!E10 -> 1472000 | H10: ='0314'!H10+'0315'!D8 -> 42 | I10: ='0314'!I10+'0315'!D7 -> 736
B11: 비고 | C11: 단체 명 무료 명
A12: 2 | B12: 전시명 : | C12: 어린이미술전 <우리 SUM 타볼래> | F12: 전시일: | G12: 2026. 2. 27(금) ~ 6. 28(일)
H13: 목표 매출액: | I13: 31500000
B14: 판매현황 | C14: 구분 | D14: 판매매수 | E14: 금액 | F14: 점유율
C15: 유료 | D15: 46 | E15: 266000 | F15: =G18/I13 -> 0.065063492
C16: 무료 | D16: 3
F17: 누계 총인원 | G17: 누계 총 금액 | H17: 누계 무료인원 | I17: 누계 유료인원
C18: 합계 | D18: =SUM(D15:D17) -> 49 | E18: =SUM(E15:E17) -> 266000 | F18: ='0314'!F18+'0315'!D18 -> 386 | G18: ='0314'!G18+'0315'!E18 -> 2049500 | H18: ='0314'!H18+'0315'!D16 -> 21 | I18: ='0314'!I18+'0315'!D15 -> 365
B19: 비고 | C19: 단체 명 무료 3명

Sheet 0317
A1: 기획전시 판매현황 | H1: 팀 장
H3: 46098
A4: 1 | B4: 전시명 : | C4: 창작스튜디오 7기 입주작가 프리뷰 | F4: 전시일: | G4: 2026. 2. 13(금) ~ 3. 22(일)
H5: 목표 매출액: | I5: 2080000
B6: 판매현황 | C6: 구분 | D6: 판매매수 | E6: 금액 | F6: 점유율
C7: 유료 | D7: 4 | E7: 8000 | F7: =G10/I5 -> 0.71153846
C8: 무료 | D8: 3
F9: 누계 총인원 | G9: 누계 총 금액 | H9: 누계 무료인원 | I9: 누계 유료인원
C10: 합계 | D10: =SUM(D7:D9) -> 7 | E10: =SUM(E7:E9) -> 8000 | F10: ='0315'!F10+'0317'!D10 -> 785 | G10: ='0315'!G10+'0317'!E10 -> 1480000 | H10: ='0315'!H10+'0317'!D8 -> 45 | I10: ='0315'!I10+'0317'!D7 -> 740
B11: 비고 | C11: 단체 명 무료 3명
A12: 2 | B12: 전시명 : | C12: 어린이미술전 <우리 SUM 타볼래> | F12: 전시일: | G12: 2026. 2. 27(금) ~ 6. 28(일)
H13: 목표 매출액: | I13: 31500000
B14: 판매현황 | C14: 구분 | D14: 판매매수 | E14: 금액 | F14: 점유율
C15: 유료 | D15: 5 | E15: 27000 | F15: =G18/I13 -> 0.065920635
C16: 무료 | D16: 5
F17: 누계 총인원 | G17: 누계 총 금액 | H17: 누계 무료인원 | I17: 누계 유료인원
C18: 합계 | D18: =SUM(D15:D17) -> 10 | E18: =SUM(E15:E17) -> 27000 | F18: ='0315'!F18+'0317'!D18 -> 396 | G18: ='0315'!G18+'0317'!E18 -> 2076500 | H18: ='0315'!H18+'0317'!D16 -> 26 | I18: ='0315'!I18+'0317'!D15 -> 370
B19: 비고 | C19: 단체 명 무료 5명

Sheet 0318
A1: 기획전시 판매현황 | H1: 팀 장
H3: 46099
A4: 1 | B4: 전시명 : | C4: 창작스튜디오 7기 입주작가 프리뷰 | F4: 전시일: | G4: 2026. 2. 13(금) ~ 3. 22(일)
H5: 목표 매출액: | I5: 2080000
B6: 판매현황 | C6: 구분 | D6: 판매매수 | E6: 금액 | F6: 점유율
C7: 유료 | D7: 15 | E7: 30000 | F7: =G10/I5 -> 0.72596154
C8: 무료 | D8: 0
F9: 누계 총인원 | G9: 누계 총 금액 | H9: 누계 무료인원 | I9: 누계 유료인원
C10: 합계 | D10: =SUM(D7:D9) -> 15 | E10: =SUM(E7:E9) -> 30000 | F10: ='0317'!F10+'0318'!D10 -> 800 | G10: ='0317'!G10+'0318'!E10 -> 1510000 | H10: ='0317'!H10+'0318'!D8 -> 45 | I10: ='0317'!I10+'0318'!D7 -> 755
B11: 비고 | C11: 단체 명 무료 명
A12: 2 | B12: 전시명 : | C12: 어린이미술전 <우리 SUM 타볼래> | F12: 전시일: | G12: 2026. 2. 27(금) ~ 6. 28(일)
H13: 목표 매출액: | I13: 31500000
B14: 판매현황 | C14: 구분 | D14: 판매매수 | E14: 금액 | F14: 점유율
C15: 유료 | D15: 5 | E15: 29000 | F15: =G18/I13 -> 0.06684127
C16: 무료 | D16: 2
F17: 누계 총인원 | G17: 누계 총 금액 | H17: 누계 무료인원 | I17: 누계 유료인원
C18: 합계 | D18: =SUM(D15:D17) -> 7 | E18: =SUM(E15:E17) -> 29000 | F18: ='0317'!F18+'0318'!D18 -> 403 | G18: ='0317'!G18+'0318'!E18 -> 2105500 | H18: ='0317'!H18+'0318'!D16 -> 28 | I18: ='0317'!I18+'0318'!D15 -> 375
B19: 비고 | C19: 단체 명 무료 2명

Sheet 0319
A1: 기획전시 판매현황 | H1: 팀 장
H3: 46100
A4: 1 | B4: 전시명 : | C4: 창작스튜디오 7기 입주작가 프리뷰 | F4: 전시일: | G4: 2026. 2. 13(금) ~ 3. 22(일)
H5: 목표 매출액: | I5: 2080000
B6: 판매현황 | C6: 구분 | D6: 판매매수 | E6: 금액 | F6: 점유율
C7: 유료 | D7: 15 | E7: 30000 | F7: =G10/I5 -> 0.74038462
C8: 무료 | D8: 0
D9: 24 | F9: 누계 총인원 | G9: 누계 총 금액 | H9: 누계 무료인원 | I9: 누계 유료인원
C10: 합계 | D10: =SUM(D7:D9) -> 39 | E10: =SUM(E7:E9) -> 30000 | F10: ='0318'!F10+'0319'!D10 -> 839 | G10: ='0318'!G10+'0319'!E10 -> 1540000 | H10: ='0318'!H10+'0319'!D8 -> 45 | I10: ='0318'!I10+'0319'!D7 -> 770
B11: 비고 | C11: 단체 명 무료 명
A12: 2 | B12: 전시명 : | C12: 어린이미술전 <우리 SUM 타볼래> | F12: 전시일: | G12: 2026. 2. 27(금) ~ 6. 28(일)
H13: 목표 매출액: | I13: 31500000
B14: 판매현황 | C14: 구분 | D14: 판매매수 | E14: 금액 | F14: 점유율
C15: 유료 | D15: 7 | E15: 35000 | F15: =G18/I13 -> 0.067952381
C16: 무료 | D16: 2
F17: 누계 총인원 | G17: 누계 총 금액 | H17: 누계 무료인원 | I17: 누계 유료인원
C18: 합계 | D18: =SUM(D15:D17) -> 9 | E18: =SUM(E15:E17) -> 35000 | F18: ='0318'!F18+'0319'!D18 -> 412 | G18: ='0318'!G18+'0319'!E18 -> 2140500 | H18: ='0318'!H18+'0319'!D16 -> 30 | I18: ='0318'!I18+'0319'!D15 -> 382
B19: 비고 | C19: 단체 명 무료 2명

Sheet 0320
A1: 기획전시 판매현황 | H1: 팀 장
H3: 46101
A4: 1 | B4: 전시명 : | C4: 창작스튜디오 7기 입주작가 프리뷰 | F4: 전시일: | G4: 2026. 2. 13(금) ~ 3. 22(일)
H5: 목표 매출액: | I5: 2080000
B6: 판매현황 | C6: 구분 | D6: 판매매수 | E6: 금액 | F6: 점유율
C7: 유료 | D7: 4 | E7: 8000 | F7: =G10/I5 -> 0.74423077
C8: 무료 | D8: 3
F9: 누계 총인원 | G9: 누계 총 금액 | H9: 누계 무료인원 | I9: 누계 유료인원
C10: 합계 | D10: =SUM(D7:D9) -> 7 | E10: =SUM(E7:E9) -> 8000 | F10: ='0319'!F10+'0320'!D10 -> 846 | G10: ='0319'!G10+'0320'!E10 -> 1548000 | H10: ='0319'!H10+'0320'!D8 -> 48 | I10: ='0319'!I10+'0320'!D7 -> 774
B11: 비고 | C11: 단체 명 무료 3명
A12: 2 | B12: 전시명 : | C12: 어린이미술전 <우리 SUM 타볼래> | F12: 전시일: | G12: 2026. 2. 27(금) ~ 6. 28(일)
H13: 목표 매출액: | I13: 31500000
B14: 판매현황 | C14: 구분 | D14: 판매매수 | E14: 금액 | F14: 점유율
C15: 유료 | D15: 24 | E15: 148000 | F15: =G18/I13 -> 0.072650794
C16: 무료 | D16: 0
F17: 누계 총인원 | G17: 누계 총 금액 | H17: 누계 무료인원 | I17: 누계 유료인원
C18: 합계 | D18: =SUM(D15:D17) -> 24 | E18: =SUM(E15:E17) -> 148000 | F18: ='0319'!F18+'0320'!D18 -> 436 | G18: ='0319'!G18+'0320'!E18 -> 2288500 | H18: ='0319'!H18+'0320'!D16 -> 30 | I18: ='0319'!I18+'0320'!D15 -> 406
B19: 비고 | C19: 단체 명 무료 명

Sheet 0321
A1: 기획전시 판매현황 | H1: 팀 장
H3: 46102
A4: 1 | B4: 전시명 : | C4: 창작스튜디오 7기 입주작가 프리뷰 | F4: 전시일: | G4: 2026. 2. 13(금) ~ 3. 22(일)
H5: 목표 매출액: | I5: 2080000
B6: 판매현황 | C6: 구분 | D6: 판매매수 | E6: 금액 | F6: 점유율
C7: 유료 | D7: 32 | E7: 64000 | F7: =G10/I5 -> 0.775
C8: 무료 | D8: 2
F9: 누계 총인원 | G9: 누계 총 금액 | H9: 누계 무료인원 | I9: 누계 유료인원
C10: 합계 | D10: =SUM(D7:D9) -> 34 | E10: =SUM(E7:E9) -> 64000 | F10: ='0320'!F10+'0321'!D10 -> 880 | G10: ='0320'!G10+'0321'!E10 -> 1612000 | H10: ='0320'!H10+'0321'!D8 -> 50 | I10: ='0320'!I10+'0321'!D7 -> 806
B11: 비고 | C11: 단체 명 무료 2명
A12: 2 | B12: 전시명 : | C12: 어린이미술전 <우리 SUM 타볼래> | F12: 전시일: | G12: 2026. 2. 27(금) ~ 6. 28(일)
H13: 목표 매출액: | I13: 31500000
B14: 판매현황 | C14: 구분 | D14: 판매매수 | E14: 금액 | F14: 점유율
C15: 유료 | D15: 77 | E15: 431000 | F15: =G18/I13 -> 0.086333333
C16: 무료 | D16: 5
F17: 누계 총인원 | G17: 누계 총 금액 | H17: 누계 무료인원 | I17: 누계 유료인원
C18: 합계 | D18: =SUM(D15:D17) -> 82 | E18: =SUM(E15:E17) -> 431000 | F18: ='0320'!F18+'0321'!D18 -> 518 | G18: ='0320'!G18+'0321'!E18 -> 2719500 | H18: ='0320'!H18+'0321'!D16 -> 35 | I18: ='0320'!I18+'0321'!D15 -> 483
B19: 비고 | C19: 단체 명 무료 5명

Sheet 0322
A1: 기획전시 판매현황 | H1: 팀 장
H3: 46103
A4: 1 | B4: 전시명 : | C4: 창작스튜디오 7기 입주작가 프리뷰 | F4: 전시일: | G4: 2026. 2. 13(금) ~ 3. 22(일)
H5: 목표 매출액: | I5: 2080000
B6: 판매현황 | C6: 구분 | D6: 판매매수 | E6: 금액 | F6: 점유율
C7: 유료 | D7: 22 | E7: 44000 | F7: =G10/I5 -> 0.79615385
C8: 무료 | D8: 0
F9: 누계 총인원 | G9: 누계 총 금액 | H9: 누계 무료인원 | I9: 누계 유료인원
C10: 합계 | D10: =SUM(D7:D9) -> 22 | E10: =SUM(E7:E9) -> 44000 | F10: ='0321'!F10+'0322'!D10 -> 902 | G10: ='0321'!G10+'0322'!E10 -> 1656000 | H10: ='0321'!H10+'0322'!D8 -> 50 | I10: ='0321'!I10+'0322'!D7 -> 828
B11: 비고 | C11: 단체 명 무료 명
A12: 2 | B12: 전시명 : | C12: 어린이미술전 <우리 SUM 타볼래> | F12: 전시일: | G12: 2026. 2. 27(금) ~ 6. 28(일)
H13: 목표 매출액: | I13: 31500000
B14: 판매현황 | C14: 구분 | D14: 판매매수 | E14: 금액 | F14: 점유율
C15: 유료 | D15: 86 | E15: 496000 | F15: =G18/I13 -> 0.10207937
C16: 무료 | D16: 5
F17: 누계 총인원 | G17: 누계 총 금액 | H17: 누계 무료인원 | I17: 누계 유료인원
C18: 합계 | D18: =SUM(D15:D17) -> 91 | E18: =SUM(E15:E17) -> 496000 | F18: ='0321'!F18+'0322'!D18 -> 609 | G18: ='0321'!G18+'0322'!E18 -> 3215500 | H18: ='0321'!H18+'0322'!D16 -> 40 | I18: ='0321'!I18+'0322'!D15 -> 569
B19: 비고 | C19: 단체 명 무료 명

Sheet 0324
A1: 기획전시 판매현황 | H1: 팀 장
H3: 46105
A4: 1 | B4: 전시명 :
H5: 목표 매출액:
B6: 판매현황 | C6: 구분 | D6: 판매매수 | E6: 금액 | F6: 점유율
C7: 유료
C8: 무료
F9: 누계 총인원 | G9: 누계 총 금액 | H9: 누계 무료인원 | I9: 누계 유료인원
C10: 합계 | D10: =SUM(D7:D9) -> 0 | E10: =SUM(E7:E9) -> 0
B11: 비고 | C11: 단체 명 무료 명
A12: 2 | B12: 전시명 : | C12: 어린이미술전 <우리 SUM 타볼래> | F12: 전시일: | G12: 2026. 2. 27(금) ~ 6. 28(일)
H13: 목표 매출액: | I13: 31500000
B14: 판매현황 | C14: 구분 | D14: 판매매수 | E14: 금액 | F14: 점유율
C15: 유료 | D15: 10 | E15: 50000 | F15: =G18/I13 -> 0.10366667
C16: 무료
F17: 누계 총인원 | G17: 누계 총 금액 | H17: 누계 무료인원 | I17: 누계 유료인원
C18: 합계 | D18: =SUM(D15:D17) -> 10 | E18: =SUM(E15:E17) -> 50000 | F18: ='0322'!F18+'0324'!D18 -> 619 | G18: ='0322'!G18+'0324'!E18 -> 3265500 | H18: ='0322'!H18+'0324'!D16 -> 40 | I18: ='0322'!I18+'0324'!D15 -> 579
B19: 비고 | C19: 단체 명 무료 명

Sheet 0325
A1: 기획전시 판매현황 | H1: 팀 장
H3: 46106
A4: 1 | B4: 전시명 :
H5: 목표 매출액:
B6: 판매현황 | C6: 구분 | D6: 판매매수 | E6: 금액 | F6: 점유율
C7: 유료
C8: 무료
F9: 누계 총인원 | G9: 누계 총 금액 | H9: 누계 무료인원 | I9: 누계 유료인원
C10: 합계 | D10: =SUM(D7:D9) -> 0 | E10: =SUM(E7:E9) -> 0
B11: 비고 | C11: 단체 명 무료 명
A12: 2 | B12: 전시명 : | C12: 어린이미술전 <우리 SUM 타볼래> | F12: 전시일: | G12: 2026. 2. 27(금) ~ 6. 28(일)
H13: 목표 매출액: | I13: 31500000
B14: 판매현황 | C14: 구분 | D14: 판매매수 | E14: 금액 | F14: 점유율
C15: 유료 | D15: 2 | E15: 12000 | F15: =G18/I13 -> 0.10404762
C16: 무료 | D16: 2
F17: 누계 총인원 | G17: 누계 총 금액 | H17: 누계 무료인원 | I17: 누계 유료인원
C18: 합계 | D18: =SUM(D15:D17) -> 4 | E18: =SUM(E15:E17) -> 12000 | F18: ='0324'!F18+'0325'!D18 -> 623 | G18: ='0324'!G18+'0325'!E18 -> 3277500 | H18: ='0324'!H18+'0325'!D16 -> 42 | I18: ='0324'!I18+'0325'!D15 -> 581
B19: 비고 | C19: 단체 명 무료 2명

Sheet 0326
A1: 기획전시 판매현황 | H1: 팀 장
H3: 46107
A4: 1 | B4: 전시명 :
H5: 목표 매출액:
B6: 판매현황 | C6: 구분 | D6: 판매매수 | E6: 금액 | F6: 점유율
C7: 유료
C8: 무료
F9: 누계 총인원 | G9: 누계 총 금액 | H9: 누계 무료인원 | I9: 누계 유료인원
C10: 합계 | D10: =SUM(D7:D9) -> 0 | E10: =SUM(E7:E9) -> 0
B11: 비고 | C11: 단체 명 무료 명
A12: 2 | B12: 전시명 : | C12: 어린이미술전 <우리 SUM 타볼래> | F12: 전시일: | G12: 2026. 2. 27(금) ~ 6. 28(일)
H13: 목표 매출액: | I13: 31500000
B14: 판매현황 | C14: 구분 | D14: 판매매수 | E14: 금액 | F14: 점유율
C15: 유료 | D15: 4 | E15: 22000 | F15: =G18/I13 -> 0.10474603
C16: 무료 | D16: 1
F17: 누계 총인원 | G17: 누계 총 금액 | H17: 누계 무료인원 | I17: 누계 유료인원
C18: 합계 | D18: =SUM(D15:D17) -> 5 | E18: =SUM(E15:E17) -> 22000 | F18: ='0325'!F18+'0326'!D18 -> 628 | G18: ='0325'!G18+'0326'!E18 -> 3299500 | H18: ='0325'!H18+'0326'!D16 -> 43 | I18: ='0325'!I18+'0326'!D15 -> 585
B19: 비고 | C19: 단체 명 무료 1명

Sheet 0327
A1: 기획전시 판매현황 | H1: 팀 장
H3: 46108
A4: 1 | B4: 전시명 : | C4: 섬냥이 in 장도 | F4: 전시일: | G4: 2026. 3. 27(금) ~ 6. 21(일)
H5: 목표 매출액: | I5: 10000000
B6: 판매현황 | C6: 구분 | D6: 판매매수 | E6: 금액 | F6: 점유율
C7: 유료 | D7: 2 | E7: 6000 | F7: =G10/I5 -> 0.0006
C8: 무료 | D8: 4
F9: 누계 총인원 | G9: 누계 총 금액 | H9: 누계 무료인원 | I9: 누계 유료인원
C10: 합계 | D10: =SUM(D7:D9) -> 6 | E10: =SUM(E7:E9) -> 6000 | F10: =D10 -> 6 | G10: =E10 -> 6000 | H10: =D8 -> 4 | I10: =D7 -> 2
B11: 비고 | C11: 단체 명 무료 4명
A12: 2 | B12: 전시명 : | C12: 어린이미술전 <우리 SUM 타볼래> | F12: 전시일: | G12: 2026. 2. 27(금) ~ 6. 28(일)
H13: 목표 매출액: | I13: 31500000
B14: 판매현황 | C14: 구분 | D14: 판매매수 | E14: 금액 | F14: 점유율
C15: 유료 | D15: 8 | E15: 48000 | F15: =G18/I13 -> 0.10626984
C16: 무료 | D16: 3
F17: 누계 총인원 | G17: 누계 총 금액 | H17: 누계 무료인원 | I17: 누계 유료인원
C18: 합계 | D18: =SUM(D15:D17) -> 11 | E18: =SUM(E15:E17) -> 48000 | F18: ='0326'!F18+'0327'!D18 -> 639 | G18: ='0326'!G18+'0327'!E18 -> 3347500 | H18: ='0326'!H18+'0327'!D16 -> 46 | I18: ='0326'!I18+'0327'!D15 -> 593
B19: 비고 | C19: 단체 명 무료 3명

Sheet 0328
A1: 기획전시 판매현황 | H1: 팀 장
H3: 46109
A4: 1 | B4: 전시명 : | C4: 섬냥이 in 장도 | F4: 전시일: | G4: 2026. 3. 27(금) ~ 6. 21(일)
H5: 목표 매출액: | I5: 10000000
B6: 판매현황 | C6: 구분 | D6: 판매매수 | E6: 금액 | F6: 점유율
C7: 유료 | D7: 89 | E7: 267000 | F7: =G10/I5 -> 0.0273
C8: 무료 | D8: 0
F9: 누계 총인원 | G9: 누계 총 금액 | H9: 누계 무료인원 | I9: 누계 유료인원
C10: 합계 | D10: =SUM(D7:D9) -> 89 | E10: =SUM(E7:E9) -> 267000 | F10: ='0327'!F10+'0328'!D10 -> 95 | G10: ='0327'!G10+'0328'!E10 -> 273000 | H10: ='0327'!H10+'0328'!D8 -> 4 | I10: ='0327'!I10+'0328'!D7 -> 91
B11: 비고 | C11: 단체 명 무료 명
A12: 2 | B12: 전시명 : | C12: 어린이미술전 <우리 SUM 타볼래> | F12: 전시일: | G12: 2026. 2. 27(금) ~ 6. 28(일)
H13: 목표 매출액: | I13: 31500000
B14: 판매현황 | C14: 구분 | D14: 판매매수 | E14: 금액 | F14: 점유율
C15: 유료 | D15: 54 | E15: 318000 | F15: =G18/I13 -> 0.11636508
C16: 무료 | D16: 4
F17: 누계 총인원 | G17: 누계 총 금액 | H17: 누계 무료인원 | I17: 누계 유료인원
C18: 합계 | D18: =SUM(D15:D17) -> 58 | E18: =SUM(E15:E17) -> 318000 | F18: ='0327'!F18+'0328'!D18 -> 697 | G18: ='0327'!G18+'0328'!E18 -> 3665500 | H18: ='0327'!H18+'0328'!D16 -> 50 | I18: ='0327'!I18+'0328'!D15 -> 647
B19: 비고 | C19: 단체 명 무료 4명

Sheet 0329
A1: 기획전시 판매현황 | H1: 팀 장
H3: 46110
A4: 1 | B4: 전시명 : | C4: 섬냥이 in 장도 | F4: 전시일: | G4: 2026. 3. 27(금) ~ 6. 21(일)
H5: 목표 매출액: | I5: 10000000
B6: 판매현황 | C6: 구분 | D6: 판매매수 | E6: 금액 | F6: 점유율
C7: 유료 | D7: 63 | E7: 189000 | F7: =G10/I5 -> 0.0462
C8: 무료 | D8: 0
F9: 누계 총인원 | G9: 누계 총 금액 | H9: 누계 무료인원 | I9: 누계 유료인원
C10: 합계 | D10: =SUM(D7:D9) -> 63 | E10: =SUM(E7:E9) -> 189000 | F10: ='0328'!F10+'0329'!D10 -> 158 | G10: ='0328'!G10+'0329'!E10 -> 462000 | H10: ='0328'!H10+'0329'!D8 -> 4 | I10: ='0328'!I10+'0329'!D7 -> 154
B11: 비고 | C11: 단체 명 무료 명
A12: 2 | B12: 전시명 : | C12: 어린이미술전 <우리 SUM 타볼래> | F12: 전시일: | G12: 2026. 2. 27(금) ~ 6. 28(일)
H13: 목표 매출액: | I13: 31500000
B14: 판매현황 | C14: 구분 | D14: 판매매수 | E14: 금액 | F14: 점유율
C15: 유료 | D15: 32 | E15: 170000 | F15: =G18/I13 -> 0.1217619
C16: 무료 | D16: 1
F17: 누계 총인원 | G17: 누계 총 금액 | H17: 누계 무료인원 | I17: 누계 유료인원
C18: 합계 | D18: =SUM(D15:D17) -> 33 | E18: =SUM(E15:E17) -> 170000 | F18: ='0328'!F18+'0329'!D18 -> 730 | G18: ='0328'!G18+'0329'!E18 -> 3835500 | H18: ='0328'!H18+'0329'!D16 -> 51 | I18: 96
B19: 비고 | C19: 단체 명 무료 1명

Sheet 0331
A1: 기획전시 판매현황 | H1: 팀 장
H3: 46112
A4: 1 | B4: 전시명 : | C4: 섬냥이 in 장도 | F4: 전시일: | G4: 2026. 3. 27(금) ~ 6. 21(일)
H5: 목표 매출액: | I5: 10000000
B6: 판매현황 | C6: 구분 | D6: 판매매수 | E6: 금액 | F6: 점유율
C7: 유료 | D7: 8 | E7: 24000 | F7: =G10/I5 -> 0.0486
C8: 무료 | D8: 0
F9: 누계 총인원 | G9: 누계 총 금액 | H9: 누계 무료인원 | I9: 누계 유료인원
C10: 합계 | D10: =SUM(D7:D9) -> 8 | E10: =SUM(E7:E9) -> 24000 | F10: ='0329'!F10+'0331'!D10 -> 166 | G10: ='0329'!G10+'0331'!E10 -> 486000 | H10: ='0329'!H10+'0331'!D8 -> 4 | I10: ='0329'!I10+'0331'!D7 -> 162
B11: 비고 | C11: 단체 명 무료 명
A12: 2 | B12: 전시명 : | C12: 어린이미술전 <우리 SUM 타볼래> | F12: 전시일: | G12: 2026. 2. 27(금) ~ 6. 28(일)
H13: 목표 매출액: | I13: 31500000
B14: 판매현황 | C14: 구분 | D14: 판매매수 | E14: 금액 | F14: 점유율
C15: 유료 | D15: 5 | E15: 27000 | F15: =G18/I13 -> 0.12261905
C16: 무료 | D16: 1
F17: 누계 총인원 | G17: 누계 총 금액 | H17: 누계 무료인원 | I17: 누계 유료인원
C18: 합계 | D18: =SUM(D15:D17) -> 6 | E18: =SUM(E15:E17) -> 27000 | F18: ='0329'!F18+'0331'!D18 -> 736 | G18: ='0329'!G18+'0331'!E18 -> 3862500 | H18: ='0329'!H18+'0331'!D16 -> 52 | I18: ='0329'!I18+'0331'!D15 -> 101
B19: 비고 | C19: 단체 명 무료 명

Sheet 0401
A1: 기획전시 판매현황 | H1: 팀 장
H3: 46113
A4: 1 | B4: 전시명 : | C4: 섬냥이 in 장도 | F4: 전시일: | G4: 2026. 3. 27(금) ~ 6. 21(일)
H5: 목표 매출액: | I5: 10000000
B6: 판매현황 | C6: 구분 | D6: 판매매수 | E6: 금액 | F6: 점유율
C7: 유료 | D7: 9 | E7: 27000 | F7: =G10/I5 -> 0.0513
C8: 무료 | D8: 0
F9: 누계 총인원 | G9: 누계 총 금액 | H9: 누계 무료인원 | I9: 누계 유료인원
C10: 합계 | D10: =SUM(D7:D9) -> 9 | E10: =SUM(E7:E9) -> 27000 | F10: ='0331'!F10+'0401'!D10 -> 175 | G10: ='0331'!G10+'0401'!E10 -> 513000 | H10: ='0331'!H10+'0401'!D8 -> 4 | I10: ='0331'!I10+'0401'!D7 -> 171
B11: 비고 | C11: 단체 명 무료 명
A12: 2 | B12: 전시명 : | C12: 어린이미술전 <우리 SUM 타볼래> | F12: 전시일: | G12: 2026. 2. 27(금) ~ 6. 28(일)
H13: 목표 매출액: | I13: 31500000
B14: 판매현황 | C14: 구분 | D14: 판매매수 | E14: 금액 | F14: 점유율
C15: 유료 | D15: 5 | E15: 29000 | F15: =G18/I13 -> 0.12353968
C16: 무료 | D16: 0
F17: 누계 총인원 | G17: 누계 총 금액 | H17: 누계 무료인원 | I17: 누계 유료인원
C18: 합계 | D18: =SUM(D15:D17) -> 5 | E18: =SUM(E15:E17) -> 29000 | F18: ='0331'!F18+'0401'!D18 -> 741 | G18: ='0331'!G18+'0401'!E18 -> 3891500 | H18: ='0331'!H18+'0401'!D16 -> 52 | I18: ='0331'!I18+'0401'!D15 -> 106
B19: 비고 | C19: 단체 명 무료 명

Sheet 0402
A1: 기획전시 판매현황 | H1: 팀 장
H3: 46114
A4: 1 | B4: 전시명 : | C4: 섬냥이 in 장도 | F4: 전시일: | G4: 2026. 3. 27(금) ~ 6. 21(일)
H5: 목표 매출액: | I5: 10000000
B6: 판매현황 | C6: 구분 | D6: 판매매수 | E6: 금액 | F6: 점유율
C7: 유료 | D7: 12 | E7: 36000 | F7: =G10/I5 -> 0.0549
C8: 무료 | D8: 1
F9: 누계 총인원 | G9: 누계 총 금액 | H9: 누계 무료인원 | I9: 누계 유료인원
C10: 합계 | D10: =SUM(D7:D9) -> 13 | E10: =SUM(E7:E9) -> 36000 | F10: ='0401'!F10+'0402'!D10 -> 188 | G10: ='0401'!G10+'0402'!E10 -> 549000 | H10: ='0401'!H10+'0402'!D8 -> 5 | I10: ='0401'!I10+'0402'!D7 -> 183
B11: 비고 | C11: 단체 명 무료 1명
A12: 2 | B12: 전시명 : | C12: 어린이미술전 <우리 SUM 타볼래> | F12: 전시일: | G12: 2026. 2. 27(금) ~ 6. 28(일)
H13: 목표 매출액: | I13: 31500000
B14: 판매현황 | C14: 구분 | D14: 판매매수 | E14: 금액 | F14: 점유율
C15: 유료 | D15: 16 | E15: 84000 | F15: =G18/I13 -> 0.12620635
C16: 무료 | D16: 1
F17: 누계 총인원 | G17: 누계 총 금액 | H17: 누계 무료인원 | I17: 누계 유료인원
C18: 합계 | D18: =SUM(D15:D17) -> 17 | E18: =SUM(E15:E17) -> 84000 | F18: ='0401'!F18+'0402'!D18 -> 758 | G18: ='0401'!G18+'0402'!E18 -> 3975500 | H18: ='0401'!H18+'0402'!D16 -> 53 | I18: ='0401'!I18+'0402'!D15 -> 122
B19: 비고 | C19: 단체 명 무료 1명

Sheet 0403
A1: 기획전시 판매현황 | H1: 팀 장
H3: 46115
A4: 1 | B4: 전시명 : | C4: 섬냥이 in 장도 | F4: 전시일: | G4: 2026. 3. 27(금) ~ 6. 21(일)
H5: 목표 매출액: | I5: 10000000
B6: 판매현황 | C6: 구분 | D6: 판매매수 | E6: 금액 | F6: 점유율
C7: 유료 | D7: 37 | E7: 111000 | F7: =G10/I5 -> 0.066
C8: 무료 | D8: 0
F9: 누계 총인원 | G9: 누계 총 금액 | H9: 누계 무료인원 | I9: 누계 유료인원
C10: 합계 | D10: =SUM(D7:D9) -> 37 | E10: =SUM(E7:E9) -> 111000 | F10: ='0402'!F10+'0403'!D10 -> 225 | G10: ='0402'!G10+'0403'!E10 -> 660000 | H10: ='0402'!H10+'0403'!D8 -> 5 | I10: ='0402'!I10+'0403'!D7 -> 220
B11: 비고 | C11: 단체 10명 무료 명
A12: 2 | B12: 전시명 : | C12: 어린이미술전 <우리 SUM 타볼래> | F12: 전시일: | G12: 2026. 2. 27(금) ~ 6. 28(일)
H13: 목표 매출액: | I13: 31500000
B14: 판매현황 | C14: 구분 | D14: 판매매수 | E14: 금액 | F14: 점유율
C15: 유료 | D15: 14 | E15: 72000 | F15: =G18/I13 -> 0.12849206
C16: 무료 | D16: 3
F17: 누계 총인원 | G17: 누계 총 금액 | H17: 누계 무료인원 | I17: 누계 유료인원
C18: 합계 | D18: =SUM(D15:D17) -> 17 | E18: =SUM(E15:E17) -> 72000 | F18: ='0402'!F18+'0403'!D18 -> 775 | G18: ='0402'!G18+'0403'!E18 -> 4047500 | H18: ='0402'!H18+'0403'!D16 -> 56 | I18: ='0402'!I18+'0403'!D15 -> 136
B19: 비고 | C19: 단체 10명 무료 3명

Sheet 0404
A1: 기획전시 판매현황 | H1: 팀 장
H3: 46116
A4: 1 | B4: 전시명 : | C4: 섬냥이 in 장도 | F4: 전시일: | G4: 2026. 3. 27(금) ~ 6. 21(일)
H5: 목표 매출액: | I5: 10000000
B6: 판매현황 | C6: 구분 | D6: 판매매수 | E6: 금액 | F6: 점유율
C7: 유료 | D7: 65 | E7: 195000 | F7: =G10/I5 -> 0.0855
C8: 무료 | D8: 1
F9: 누계 총인원 | G9: 누계 총 금액 | H9: 누계 무료인원 | I9: 누계 유료인원
C10: 합계 | D10: =SUM(D7:D9) -> 66 | E10: =SUM(E7:E9) -> 195000 | F10: ='0403'!F10+'0404'!D10 -> 291 | G10: ='0403'!G10+'0404'!E10 -> 855000 | H10: ='0403'!H10+'0404'!D8 -> 6 | I10: ='0403'!I10+'0404'!D7 -> 285
B11: 비고 | C11: 단체 명 무료 1명
A12: 2 | B12: 전시명 : | C12: 어린이미술전 <우리 SUM 타볼래> | F12: 전시일: | G12: 2026. 2. 27(금) ~ 6. 28(일)
H13: 목표 매출액: | I13: 31500000
B14: 판매현황 | C14: 구분 | D14: 판매매수 | E14: 금액 | F14: 점유율
C15: 유료 | D15: 53 | E15: 299000 | F15: =G18/I13 -> 0.13798413
C16: 무료 | D16: 1
F17: 누계 총인원 | G17: 누계 총 금액 | H17: 누계 무료인원 | I17: 누계 유료인원
C18: 합계 | D18: =SUM(D15:D17) -> 54 | E18: =SUM(E15:E17) -> 299000 | F18: ='0403'!F18+'0404'!D18 -> 829 | G18: ='0403'!G18+'0404'!E18 -> 4346500 | H18: ='0403'!H18+'0404'!D16 -> 57 | I18: ='0403'!I18+'0404'!D15 -> 189
B19: 비고 | C19: 단체 명 무료 1명

Sheet 0405
A1: 기획전시 판매현황 | H1: 팀 장
H3: 46117
A4: 1 | B4: 전시명 : | C4: 섬냥이 in 장도 | F4: 전시일: | G4: 2026. 3. 27(금) ~ 6. 21(일)
H5: 목표 매출액: | I5: 10000000
B6: 판매현황 | C6: 구분 | D6: 판매매수 | E6: 금액 | F6: 점유율
C7: 유료 | D7: 66 | E7: 198000 | F7: =G10/I5 -> 0.1053
C8: 무료 | D8: 0
F9: 누계 총인원 | G9: 누계 총 금액 | H9: 누계 무료인원 | I9: 누계 유료인원
C10: 합계 | D10: =SUM(D7:D9) -> 66 | E10: =SUM(E7:E9) -> 198000 | F10: ='0404'!F10+'0405'!D10 -> 357 | G10: ='0404'!G10+'0405'!E10 -> 1053000 | H10: ='0404'!H10+'0405'!D8 -> 6 | I10: ='0404'!I10+'0405'!D7 -> 351
B11: 비고 | C11: 단체 명 무료 명
A12: 2 | B12: 전시명 : | C12: 어린이미술전 <우리 SUM 타볼래> | F12: 전시일: | G12: 2026. 2. 27(금) ~ 6. 28(일)
H13: 목표 매출액: | I13: 31500000
B14: 판매현황 | C14: 구분 | D14: 판매매수 | E14: 금액 | F14: 점유율
C15: 유료 | D15: 62 | E15: 366000 | F15: =G18/I13 -> 0.14960317
C16: 무료 | D16: 3
F17: 누계 총인원 | G17: 누계 총 금액 | H17: 누계 무료인원 | I17: 누계 유료인원
C18: 합계 | D18: =SUM(D15:D17) -> 65 | E18: =SUM(E15:E17) -> 366000 | F18: ='0404'!F18+'0405'!D18 -> 894 | G18: ='0404'!G18+'0405'!E18 -> 4712500 | H18: ='0404'!H18+'0405'!D16 -> 60 | I18: ='0404'!I18+'0405'!D15 -> 251
B19: 비고 | C19: 단체 명 무료 3명

Sheet 0407
A1: 기획전시 판매현황 | H1: 팀 장
H3: 46119
A4: 1 | B4: 전시명 : | C4: 섬냥이 in 장도 | F4: 전시일: | G4: 2026. 3. 27(금) ~ 6. 21(일)
H5: 목표 매출액: | I5: 10000000
B6: 판매현황 | C6: 구분 | D6: 판매매수 | E6: 금액 | F6: 점유율
C7: 유료 | D7: 54 | E7: 162000 | F7: =G10/I5 -> 0.1215
C8: 무료 | D8: 0
F9: 누계 총인원 | G9: 누계 총 금액 | H9: 누계 무료인원 | I9: 누계 유료인원
C10: 합계 | D10: =SUM(D7:D9) -> 54 | E10: =SUM(E7:E9) -> 162000 | F10: ='0405'!F10+'0407'!D10 -> 411 | G10: ='0405'!G10+'0407'!E10 -> 1215000 | H10: ='0405'!H10+'0407'!D8 -> 6 | I10: ='0405'!I10+'0407'!D7 -> 405
B11: 비고 | C11: 단체 38명 무료 명
A12: 2 | B12: 전시명 : | C12: 어린이미술전 <우리 SUM 타볼래> | F12: 전시일: | G12: 2026. 2. 27(금) ~ 6. 28(일)
H13: 목표 매출액: | I13: 31500000
B14: 판매현황 | C14: 구분 | D14: 판매매수 | E14: 금액 | F14: 점유율
C15: 유료 | D15: 50 | E15: 231000 | F15: =G18/I13 -> 0.15693651
C16: 무료 | D16: 0
F17: 누계 총인원 | G17: 누계 총 금액 | H17: 누계 무료인원 | I17: 누계 유료인원
C18: 합계 | D18: =SUM(D15:D17) -> 50 | E18: =SUM(E15:E17) -> 231000 | F18: ='0405'!F18+'0407'!D18 -> 944 | G18: ='0405'!G18+'0407'!E18 -> 4943500 | H18: ='0405'!H18+'0407'!D16 -> 60 | I18: ='0405'!I18+'0407'!D15 -> 301
B19: 비고 | C19: 단체 48명 무료 명

Sheet 0408
A1: 기획전시 판매현황 | H1: 팀 장
H3: 46120
A4: 1 | B4: 전시명 : | C4: 섬냥이 in 장도 | F4: 전시일: | G4: 2026. 3. 27(금) ~ 6. 21(일)
H5: 목표 매출액: | I5: 10000000
B6: 판매현황 | C6: 구분 | D6: 판매매수 | E6: 금액 | F6: 점유율
C7: 유료 | D7: 39 | E7: 117000 | F7: =G10/I5 -> 0.1332
C8: 무료 | D8: 2
F9: 누계 총인원 | G9: 누계 총 금액 | H9: 누계 무료인원 | I9: 누계 유료인원
C10: 합계 | D10: =SUM(D7:D9) -> 41 | E10: =SUM(E7:E9) -> 117000 | F10: ='0407'!F10+'0408'!D10 -> 452 | G10: ='0407'!G10+'0408'!E10 -> 1332000 | H10: ='0407'!H10+'0408'!D8 -> 8 | I10: ='0407'!I10+'0408'!D7 -> 444
B11: 비고 | C11: 단체 17명 무료 2명
A12: 2 | B12: 전시명 : | C12: 어린이미술전 <우리 SUM 타볼래> | F12: 전시일: | G12: 2026. 2. 27(금) ~ 6. 28(일)
H13: 목표 매출액: | I13: 31500000
B14: 판매현황 | C14: 구분 | D14: 판매매수 | E14: 금액 | F14: 점유율
C15: 유료 | D15: 53 | E15: 243500 | F15: =G18/I13 -> 0.16466667
C16: 무료 | D16: 3
F17: 누계 총인원 | G17: 누계 총 금액 | H17: 누계 무료인원 | I17: 누계 유료인원
C18: 합계 | D18: =SUM(D15:D17) -> 56 | E18: =SUM(E15:E17) -> 243500 | F18: ='0407'!F18+'0408'!D18 -> 1000 | G18: ='0407'!G18+'0408'!E18 -> 5187000 | H18: ='0407'!H18+'0408'!D16 -> 63 | I18: ='0407'!I18+'0408'!D15 -> 354
B19: 비고 | C19: 단체 47명 무료 3명

Sheet 0409
A1: 기획전시 판매현황 | H1: 팀 장
H3: 46121
A4: 1 | B4: 전시명 : | C4: 섬냥이 in 장도 | F4: 전시일: | G4: 2026. 3. 27(금) ~ 6. 21(일)
H5: 목표 매출액: | I5: 10000000
B6: 판매현황 | C6: 구분 | D6: 판매매수 | E6: 금액 | F6: 점유율
C7: 유료 | D7: 1 | E7: 3000 | F7: =G10/I5 -> 0.1335
C8: 무료 | D8: 0
F9: 누계 총인원 | G9: 누계 총 금액 | H9: 누계 무료인원 | I9: 누계 유료인원
C10: 합계 | D10: =SUM(D7:D9) -> 1 | E10: =SUM(E7:E9) -> 3000 | F10: ='0408'!F10+'0409'!D10 -> 453 | G10: ='0408'!G10+'0409'!E10 -> 1335000 | H10: ='0408'!H10+'0409'!D8 -> 8 | I10: ='0408'!I10+'0409'!D7 -> 445
B11: 비고 | C11: 단체 명 무료 명
A12: 2 | B12: 전시명 : | C12: 어린이미술전 <우리 SUM 타볼래> | F12: 전시일: | G12: 2026. 2. 27(금) ~ 6. 28(일)
H13: 목표 매출액: | I13: 31500000
B14: 판매현황 | C14: 구분 | D14: 판매매수 | E14: 금액 | F14: 점유율
C15: 유료 | D15: 15 | E15: 97000 | F15: =G18/I13 -> 0.16774603
C16: 무료 | D16: 2
F17: 누계 총인원 | G17: 누계 총 금액 | H17: 누계 무료인원 | I17: 누계 유료인원
C18: 합계 | D18: =SUM(D15:D17) -> 17 | E18: =SUM(E15:E17) -> 97000 | F18: ='0408'!F18+'0409'!D18 -> 1017 | G18: ='0408'!G18+'0409'!E18 -> 5284000 | H18: ='0408'!H18+'0409'!D16 -> 65 | I18: ='0408'!I18+'0409'!D15 -> 369
B19: 비고 | C19: 단체 12명 무료 2명 | F19: 브런치 콘서트 전시 패키지 10명 관람

Sheet 0410
A1: 기획전시 판매현황 | H1: 팀 장
H3: 46122
A4: 1 | B4: 전시명 : | C4: 섬냥이 in 장도 | F4: 전시일: | G4: 2026. 3. 27(금) ~ 6. 21(일)
H5: 목표 매출액: | I5: 10000000
B6: 판매현황 | C6: 구분 | D6: 판매매수 | E6: 금액 | F6: 점유율
C7: 유료 | D7: 25 | E7: 75000 | F7: =G10/I5 -> 0.141
C8: 무료 | D8: 5
F9: 누계 총인원 | G9: 누계 총 금액 | H9: 누계 무료인원 | I9: 누계 유료인원
C10: 합계 | D10: =SUM(D7:D9) -> 30 | E10: =SUM(E7:E9) -> 75000 | F10: ='0409'!F10+'0410'!D10 -> 483 | G10: ='0409'!G10+'0410'!E10 -> 1410000 | H10: ='0409'!H10+'0410'!D8 -> 13 | I10: ='0409'!I10+'0410'!D7 -> 470
B11: 비고 | C11: 단체 명 무료 5명
A12: 2 | B12: 전시명 : | C12: 어린이미술전 <우리 SUM 타볼래> | F12: 전시일: | G12: 2026. 2. 27(금) ~ 6. 28(일)
H13: 목표 매출액: | I13: 31500000
B14: 판매현황 | C14: 구분 | D14: 판매매수 | E14: 금액 | F14: 점유율
C15: 유료 | D15: 8 | E15: 42000 | F15: =G18/I13 -> 0.16907937
C16: 무료 | D16: 0
F17: 누계 총인원 | G17: 누계 총 금액 | H17: 누계 무료인원 | I17: 누계 유료인원
C18: 합계 | D18: =SUM(D15:D17) -> 8 | E18: =SUM(E15:E17) -> 42000 | F18: ='0409'!F18+'0410'!D18 -> 1025 | G18: ='0409'!G18+'0410'!E18 -> 5326000 | H18: ='0409'!H18+'0410'!D16 -> 65 | I18: ='0409'!I18+'0410'!D15 -> 377
B19: 비고 | C19: 단체 명 무료 명

Sheet 0411
A1: 기획전시 판매현황 | H1: 팀 장
H3: 46123
A4: 1 | B4: 전시명 : | C4: 섬냥이 in 장도 | F4: 전시일: | G4: 2026. 3. 27(금) ~ 6. 21(일)
H5: 목표 매출액: | I5: 10000000
B6: 판매현황 | C6: 구분 | D6: 판매매수 | E6: 금액 | F6: 점유율
C7: 유료 | D7: 88 | E7: 264000 | F7: =G10/I5 -> 0.1674
C8: 무료 | D8: 1
F9: 누계 총인원 | G9: 누계 총 금액 | H9: 누계 무료인원 | I9: 누계 유료인원
C10: 합계 | D10: =SUM(D7:D9) -> 89 | E10: =SUM(E7:E9) -> 264000 | F10: ='0410'!F10+'0411'!D10 -> 572 | G10: ='0410'!G10+'0411'!E10 -> 1674000 | H10: ='0410'!H10+'0411'!D8 -> 14 | I10: ='0410'!I10+'0411'!D7 -> 558
B11: 비고 | C11: 단체 16명 무료 1명
A12: 2 | B12: 전시명 : | C12: 어린이미술전 <우리 SUM 타볼래> | F12: 전시일: | G12: 2026. 2. 27(금) ~ 6. 28(일)
H13: 목표 매출액: | I13: 31500000
B14: 판매현황 | C14: 구분 | D14: 판매매수 | E14: 금액 | F14: 점유율
C15: 유료 | D15: 59 | E15: 323000 | F15: =G18/I13 -> 0.17933333
C16: 무료 | D16: 4
F17: 누계 총인원 | G17: 누계 총 금액 | H17: 누계 무료인원 | I17: 누계 유료인원
C18: 합계 | D18: =SUM(D15:D17) -> 63 | E18: =SUM(E15:E17) -> 323000 | F18: ='0410'!F18+'0411'!D18 -> 1088 | G18: ='0410'!G18+'0411'!E18 -> 5649000 | H18: ='0410'!H18+'0411'!D16 -> 69 | I18: ='0410'!I18+'0411'!D15 -> 436
B19: 비고 | C19: 단체 명 무료 4명

Sheet 0412
A1: 기획전시 판매현황 | H1: 팀 장
H3: 46124
A4: 1 | B4: 전시명 : | C4: 섬냥이 in 장도 | F4: 전시일: | G4: 2026. 3. 27(금) ~ 6. 21(일)
H5: 목표 매출액: | I5: 10000000
B6: 판매현황 | C6: 구분 | D6: 판매매수 | E6: 금액 | F6: 점유율
C7: 유료 | D7: 61 | E7: 183000 | F7: =G10/I5 -> 0.1857
C8: 무료 | D8: 2
F9: 누계 총인원 | G9: 누계 총 금액 | H9: 누계 무료인원 | I9: 누계 유료인원
C10: 합계 | D10: =SUM(D7:D9) -> 63 | E10: =SUM(E7:E9) -> 183000 | F10: ='0411'!F10+'0412'!D10 -> 635 | G10: ='0411'!G10+'0412'!E10 -> 1857000 | H10: ='0411'!H10+'0412'!D8 -> 16 | I10: ='0411'!I10+'0412'!D7 -> 619
B11: 비고 | C11: 단체 명 무료 2명
A12: 2 | B12: 전시명 : | C12: 어린이미술전 <우리 SUM 타볼래> | F12: 전시일: | G12: 2026. 2. 27(금) ~ 6. 28(일)
H13: 목표 매출액: | I13: 31500000
B14: 판매현황 | C14: 구분 | D14: 판매매수 | E14: 금액 | F14: 점유율
C15: 유료 | D15: 34 | E15: 194000 | F15: =G18/I13 -> 0.18549206
C16: 무료 | D16: 12
F17: 누계 총인원 | G17: 누계 총 금액 | H17: 누계 무료인원 | I17: 누계 유료인원
C18: 합계 | D18: =SUM(D15:D17) -> 46 | E18: =SUM(E15:E17) -> 194000 | F18: ='0411'!F18+'0412'!D18 -> 1134 | G18: ='0411'!G18+'0412'!E18 -> 5843000 | H18: ='0411'!H18+'0412'!D16 -> 81 | I18: ='0411'!I18+'0412'!D15 -> 470
B19: 비고 | C19: 단체 명 무료 12명

Sheet 0414
A1: 기획전시 판매현황 | H1: 팀 장
H3: 46126
A4: 1 | B4: 전시명 : | C4: 섬냥이 in 장도 | F4: 전시일: | G4: 2026. 3. 27(금) ~ 6. 21(일)
H5: 목표 매출액: | I5: 10000000
B6: 판매현황 | C6: 구분 | D6: 판매매수 | E6: 금액 | F6: 점유율
C7: 유료 | D7: 8 | E7: 24000 | F7: =G10/I5 -> 0.1881
C8: 무료
F9: 누계 총인원 | G9: 누계 총 금액 | H9: 누계 무료인원 | I9: 누계 유료인원
C10: 합계 | D10: =SUM(D7:D9) -> 8 | E10: =SUM(E7:E9) -> 24000 | F10: ='0412'!F10+'0414'!D10 -> 643 | G10: ='0412'!G10+'0414'!E10 -> 1881000 | H10: ='0412'!H10+'0414'!D8 -> 16 | I10: ='0412'!I10+'0414'!D7 -> 627
B11: 비고 | C11: 단체 명 무료 명
A12: 2 | B12: 전시명 : | C12: 어린이미술전 <우리 SUM 타볼래> | F12: 전시일: | G12: 2026. 2. 27(금) ~ 6. 28(일)
H13: 목표 매출액: | I13: 31500000
B14: 판매현황 | C14: 구분 | D14: 판매매수 | E14: 금액 | F14: 점유율
C15: 유료 | D15: 3 | E15: 19000 | F15: =G18/I13 -> 0.18609524
C16: 무료
F17: 누계 총인원 | G17: 누계 총 금액 | H17: 누계 무료인원 | I17: 누계 유료인원
C18: 합계 | D18: =SUM(D15:D17) -> 3 | E18: =SUM(E15:E17) -> 19000 | F18: ='0412'!F18+'0414'!D18 -> 1137 | G18: ='0412'!G18+'0414'!E18 -> 5862000 | H18: ='0412'!H18+'0414'!D16 -> 81 | I18: ='0412'!I18+'0414'!D15 -> 473
B19: 비고 | C19: 단체 명 무료 명

Sheet 0415
A1: 기획전시 판매현황 | H1: 팀 장
H3: 46127
A4: 1 | B4: 전시명 : | C4: 섬냥이 in 장도 | F4: 전시일: | G4: 2026. 3. 27(금) ~ 6. 21(일)
H5: 목표 매출액: | I5: 10000000
B6: 판매현황 | C6: 구분 | D6: 판매매수 | E6: 금액 | F6: 점유율
C7: 유료 | D7: 23 | E7: 69000 | F7: =G10/I5 -> 0.195
C8: 무료 | D8: 0
F9: 누계 총인원 | G9: 누계 총 금액 | H9: 누계 무료인원 | I9: 누계 유료인원
C10: 합계 | D10: =SUM(D7:D9) -> 23 | E10: =SUM(E7:E9) -> 69000 | F10: ='0414'!F10+'0415'!D10 -> 666 | G10: ='0414'!G10+'0415'!E10 -> 1950000 | H10: ='0414'!H10+'0415'!D8 -> 16 | I10: ='0414'!I10+'0415'!D7 -> 650
B11: 비고 | C11: 단체 명 무료 명
A12: 2 | B12: 전시명 : | C12: 어린이미술전 <우리 SUM 타볼래> | F12: 전시일: | G12: 2026. 2. 27(금) ~ 6. 28(일)
H13: 목표 매출액: | I13: 31500000
B14: 판매현황 | C14: 구분 | D14: 판매매수 | E14: 금액 | F14: 점유율
C15: 유료 | D15: 85 | E15: 461000 | F15: =G18/I13 -> 0.20073016
C16: 무료 | D16: 3
F17: 누계 총인원 | G17: 누계 총 금액 | H17: 누계 무료인원 | I17: 누계 유료인원
C18: 합계 | D18: =SUM(D15:D17) -> 88 | E18: =SUM(E15:E17) -> 461000 | F18: ='0414'!F18+'0415'!D18 -> 1225 | G18: ='0414'!G18+'0415'!E18 -> 6323000 | H18: ='0414'!H18+'0415'!D16 -> 84 | I18: ='0414'!I18+'0415'!D15 -> 558
B19: 비고 | C19: 단체 83명 무료 3명

Sheet 0416
A1: 기획전시 판매현황 | H1: 팀 장
H3: 46128
A4: 1 | B4: 전시명 : | C4: 섬냥이 in 장도 | F4: 전시일: | G4: 2026. 3. 27(금) ~ 6. 21(일)
H5: 목표 매출액: | I5: 10000000
B6: 판매현황 | C6: 구분 | D6: 판매매수 | E6: 금액 | F6: 점유율
C7: 유료 | D7: 41 | E7: 123000 | F7: =G10/I5 -> 0.2073
C8: 무료 | D8: 3
F9: 누계 총인원 | G9: 누계 총 금액 | H9: 누계 무료인원 | I9: 누계 유료인원
C10: 합계 | D10: =SUM(D7:D9) -> 44 | E10: =SUM(E7:E9) -> 123000 | F10: ='0415'!F10+'0416'!D10 -> 710 | G10: ='0415'!G10+'0416'!E10 -> 2073000 | H10: ='0415'!H10+'0416'!D8 -> 19 | I10: ='0415'!I10+'0416'!D7 -> 691
B11: 비고 | C11: 단체 21명 무료 3명
A12: 2 | B12: 전시명 : | C12: 어린이미술전 <우리 SUM 타볼래> | F12: 전시일: | G12: 2026. 2. 27(금) ~ 6. 28(일)
H13: 목표 매출액: | I13: 31500000
B14: 판매현황 | C14: 구분 | D14: 판매매수 | E14: 금액 | F14: 점유율
C15: 유료 | D15: 5 | E15: 29000 | F15: =G18/I13 -> 0.20165079
C16: 무료 | D16: 3
F17: 누계 총인원 | G17: 누계 총 금액 | H17: 누계 무료인원 | I17: 누계 유료인원
C18: 합계 | D18: =SUM(D15:D17) -> 8 | E18: =SUM(E15:E17) -> 29000 | F18: ='0415'!F18+'0416'!D18 -> 1233 | G18: ='0415'!G18+'0416'!E18 -> 6352000 | H18: ='0415'!H18+'0416'!D16 -> 87 | I18: ='0415'!I18+'0416'!D15 -> 563
B19: 비고 | C19: 단체 명 무료 3명

Sheet 0417
A1: 기획전시 판매현황 | H1: 팀 장
H3: 46129
A4: 1 | B4: 전시명 : | C4: 섬냥이 in 장도 | F4: 전시일: | G4: 2026. 3. 27(금) ~ 6. 21(일)
H5: 목표 매출액: | I5: 10000000
B6: 판매현황 | C6: 구분 | D6: 판매매수 | E6: 금액 | F6: 점유율
C7: 유료 | D7: 29 | E7: 87000 | F7: =G10/I5 -> 0.216
C8: 무료 | D8: 0
F9: 누계 총인원 | G9: 누계 총 금액 | H9: 누계 무료인원 | I9: 누계 유료인원
C10: 합계 | D10: =SUM(D7:D9) -> 29 | E10: =SUM(E7:E9) -> 87000 | F10: ='0416'!F10+'0417'!D10 -> 739 | G10: ='0416'!G10+'0417'!E10 -> 2160000 | H10: ='0416'!H10+'0417'!D8 -> 19 | I10: ='0416'!I10+'0417'!D7 -> 720
B11: 비고 | C11: 단체 명 무료 명
A12: 2 | B12: 전시명 : | C12: 어린이미술전 <우리 SUM 타볼래> | F12: 전시일: | G12: 2026. 2. 27(금) ~ 6. 28(일)
H13: 목표 매출액: | I13: 31500000
B14: 판매현황 | C14: 구분 | D14: 판매매수 | E14: 금액 | F14: 점유율
C15: 유료 | D15: 4 | E15: 24000 | F15: =G18/I13 -> 0.2024127
C16: 무료 | D16: 0
F17: 누계 총인원 | G17: 누계 총 금액 | H17: 누계 무료인원 | I17: 누계 유료인원
C18: 합계 | D18: =SUM(D15:D17) -> 4 | E18: =SUM(E15:E17) -> 24000 | F18: ='0416'!F18+'0417'!D18 -> 1237 | G18: ='0416'!G18+'0417'!E18 -> 6376000 | H18: ='0416'!H18+'0417'!D16 -> 87 | I18: ='0416'!I18+'0417'!D15 -> 567
B19: 비고 | C19: 단체 명 무료 명

Sheet 0418
A1: 기획전시 판매현황 | H1: 팀 장
H3: 46130
A4: 1 | B4: 전시명 : | C4: 섬냥이 in 장도 | F4: 전시일: | G4: 2026. 3. 27(금) ~ 6. 21(일)
H5: 목표 매출액: | I5: 10000000
B6: 판매현황 | C6: 구분 | D6: 판매매수 | E6: 금액 | F6: 점유율
C7: 유료 | D7: 57 | E7: 171000 | F7: =G10/I5 -> 0.2331
C8: 무료 | D8: 5
F9: 누계 총인원 | G9: 누계 총 금액 | H9: 누계 무료인원 | I9: 누계 유료인원
C10: 합계 | D10: =SUM(D7:D9) -> 62 | E10: =SUM(E7:E9) -> 171000 | F10: ='0417'!F10+'0418'!D10 -> 801 | G10: ='0417'!G10+'0418'!E10 -> 2331000 | H10: ='0417'!H10+'0418'!D8 -> 24 | I10: ='0417'!I10+'0418'!D7 -> 777
B11: 비고 | C11: 단체 명 무료 5명
A12: 2 | B12: 전시명 : | C12: 어린이미술전 <우리 SUM 타볼래> | F12: 전시일: | G12: 2026. 2. 27(금) ~ 6. 28(일)
H13: 목표 매출액: | I13: 31500000
B14: 판매현황 | C14: 구분 | D14: 판매매수 | E14: 금액 | F14: 점유율
C15: 유료 | D15: 74 | E15: 400000 | F15: =G18/I13 -> 0.21511111
C16: 무료 | D16: 18
F17: 누계 총인원 | G17: 누계 총 금액 | H17: 누계 무료인원 | I17: 누계 유료인원
C18: 합계 | D18: =SUM(D15:D17) -> 92 | E18: =SUM(E15:E17) -> 400000 | F18: ='0417'!F18+'0418'!D18 -> 1329 | G18: ='0417'!G18+'0418'!E18 -> 6776000 | H18: ='0417'!H18+'0418'!D16 -> 105 | I18: ='0417'!I18+'0418'!D15 -> 641
B19: 비고 | C19: 단체 명 무료 18명(전시연계 교육 프로그램 12명 포함) | F19: 전시연계 교육 프로그램 1차시 : 참여자 9명

Sheet 0419
A1: 기획전시 판매현황 | H1: 팀 장
H3: 46131
A4: 1 | B4: 전시명 : | C4: 섬냥이 in 장도 | F4: 전시일: | G4: 2026. 3. 27(금) ~ 6. 21(일)
H5: 목표 매출액: | I5: 10000000
B6: 판매현황 | C6: 구분 | D6: 판매매수 | E6: 금액 | F6: 점유율
C7: 유료 | D7: 39 | E7: 117000 | F7: =G10/I5 -> 0.2448
C8: 무료 | D8: 1
F9: 누계 총인원 | G9: 누계 총 금액 | H9: 누계 무료인원 | I9: 누계 유료인원
C10: 합계 | D10: =SUM(D7:D9) -> 40 | E10: =SUM(E7:E9) -> 117000 | F10: ='0418'!F10+'0419'!D10 -> 841 | G10: ='0418'!G10+'0419'!E10 -> 2448000 | H10: ='0418'!H10+'0419'!D8 -> 25 | I10: ='0418'!I10+'0419'!D7 -> 816
B11: 비고 | C11: 단체 명 무료 1명
A12: 2 | B12: 전시명 : | C12: 어린이미술전 <우리 SUM 타볼래> | F12: 전시일: | G12: 2026. 2. 27(금) ~ 6. 28(일)
H13: 목표 매출액: | I13: 31500000
B14: 판매현황 | C14: 구분 | D14: 판매매수 | E14: 금액 | F14: 점유율
C15: 유료 | D15: 29 | E15: 157000 | F15: =G18/I13 -> 0.22009524
C16: 무료 | D16: 1
F17: 누계 총인원 | G17: 누계 총 금액 | H17: 누계 무료인원 | I17: 누계 유료인원
C18: 합계 | D18: =SUM(D15:D17) -> 30 | E18: =SUM(E15:E17) -> 157000 | F18: ='0418'!F18+'0419'!D18 -> 1359 | G18: ='0418'!G18+'0419'!E18 -> 6933000 | H18: ='0418'!H18+'0419'!D16 -> 106 | I18: ='0418'!I18+'0419'!D15 -> 670
B19: 비고 | C19: 단체 명 무료 1명

Sheet 0421
A1: 기획전시 판매현황 | H1: 팀 장
H3: 46133
A4: 1 | B4: 전시명 : | C4: 섬냥이 in 장도 | F4: 전시일: | G4: 2026. 3. 27(금) ~ 6. 21(일)
H5: 목표 매출액: | I5: 10000000
B6: 판매현황 | C6: 구분 | D6: 판매매수 | E6: 금액 | F6: 점유율
C7: 유료 | D7: 36 | E7: 108000 | F7: =G10/I5 -> 0.2556
C8: 무료 | D8: 0
F9: 누계 총인원 | G9: 누계 총 금액 | H9: 누계 무료인원 | I9: 누계 유료인원
C10: 합계 | D10: =SUM(D7:D9) -> 36 | E10: =SUM(E7:E9) -> 108000 | F10: ='0419'!F10+'0421'!D10 -> 877 | G10: ='0419'!G10+'0421'!E10 -> 2556000 | H10: ='0419'!H10+'0421'!D8 -> 25 | I10: ='0419'!I10+'0421'!D7 -> 852
B11: 비고 | C11: 단체 명 무료 명
A12: 2 | B12: 전시명 : | C12: 어린이미술전 <우리 SUM 타볼래> | F12: 전시일: | G12: 2026. 2. 27(금) ~ 6. 28(일)
H13: 목표 매출액: | I13: 31500000
B14: 판매현황 | C14: 구분 | D14: 판매매수 | E14: 금액 | F14: 점유율
C15: 유료 | D15: 19 | E15: 111000 | F15: =G18/I13 -> 0.22361905
C16: 무료 | D16: 0
F17: 누계 총인원 | G17: 누계 총 금액 | H17: 누계 무료인원 | I17: 누계 유료인원
C18: 합계 | D18: =SUM(D15:D17) -> 19 | E18: =SUM(E15:E17) -> 111000 | F18: ='0419'!F18+'0421'!D18 -> 1378 | G18: ='0419'!G18+'0421'!E18 -> 7044000 | H18: ='0419'!H18+'0421'!D16 -> 106 | I18: ='0419'!I18+'0421'!D15 -> 689
B19: 비고 | C19: 단체 명 무료 명

Sheet 0422
A1: 기획전시 판매현황 | H1: 팀 장
H3: 46134
A4: 1 | B4: 전시명 : | C4: 섬냥이 in 장도 | F4: 전시일: | G4: 2026. 3. 27(금) ~ 6. 21(일)
H5: 목표 매출액: | I5: 10000000
B6: 판매현황 | C6: 구분 | D6: 판매매수 | E6: 금액 | F6: 점유율
C7: 유료 | D7: 17 | E7: 51000 | F7: =G10/I5 -> 0.2607
C8: 무료 | D8: 0
F9: 누계 총인원 | G9: 누계 총 금액 | H9: 누계 무료인원 | I9: 누계 유료인원
C10: 합계 | D10: =SUM(D7:D9) -> 17 | E10: =SUM(E7:E9) -> 51000 | F10: ='0421'!F10+'0422'!D10 -> 894 | G10: ='0421'!G10+'0422'!E10 -> 2607000 | H10: ='0421'!H10+'0422'!D8 -> 25 | I10: ='0421'!I10+'0422'!D7 -> 869
B11: 비고 | C11: 단체 명 무료 명
A12: 2 | B12: 전시명 : | C12: 어린이미술전 <우리 SUM 타볼래> | F12: 전시일: | G12: 2026. 2. 27(금) ~ 6. 28(일)
H13: 목표 매출액: | I13: 31500000
B14: 판매현황 | C14: 구분 | D14: 판매매수 | E14: 금액 | F14: 점유율
C15: 유료 | D15: 14 | E15: 63000 | F15: =G18/I13 -> 0.22561905
C16: 무료 | D16: 0
F17: 누계 총인원 | G17: 누계 총 금액 | H17: 누계 무료인원 | I17: 누계 유료인원
C18: 합계 | D18: =SUM(D15:D17) -> 14 | E18: =SUM(E15:E17) -> 63000 | F18: ='0421'!F18+'0422'!D18 -> 1392 | G18: ='0421'!G18+'0422'!E18 -> 7107000 | H18: ='0421'!H18+'0422'!D16 -> 106 | I18: ='0421'!I18+'0422'!D15 -> 703
B19: 비고 | C19: 단체 14명 무료 명

Sheet 0423
A1: 기획전시 판매현황 | H1: 팀 장
H3: 46135
A4: 1 | B4: 전시명 : | C4: 섬냥이 in 장도 | F4: 전시일: | G4: 2026. 3. 27(금) ~ 6. 21(일)
H5: 목표 매출액: | I5: 10000000
B6: 판매현황 | C6: 구분 | D6: 판매매수 | E6: 금액 | F6: 점유율
C7: 유료 | D7: 21 | E7: 63000 | F7: =G10/I5 -> 0.267
C8: 무료 | D8: 0
F9: 누계 총인원 | G9: 누계 총 금액 | H9: 누계 무료인원 | I9: 누계 유료인원
C10: 합계 | D10: =SUM(D7:D9) -> 21 | E10: =SUM(E7:E9) -> 63000 | F10: ='0422'!F10+'0423'!D10 -> 915 | G10: ='0422'!G10+'0423'!E10 -> 2670000 | H10: ='0422'!H10+'0423'!D8 -> 25 | I10: ='0422'!I10+'0423'!D7 -> 890
B11: 비고 | C11: 단체 명 무료 명
A12: 2 | B12: 전시명 : | C12: 어린이미술전 <우리 SUM 타볼래> | F12: 전시일: | G12: 2026. 2. 27(금) ~ 6. 28(일)
H13: 목표 매출액: | I13: 31500000
B14: 판매현황 | C14: 구분 | D14: 판매매수 | E14: 금액 | F14: 점유율
C15: 유료 | D15: 5 | E15: 31000 | F15: =G18/I13 -> 0.22660317
C16: 무료 | D16: 0
F17: 누계 총인원 | G17: 누계 총 금액 | H17: 누계 무료인원 | I17: 누계 유료인원
C18: 합계 | D18: =SUM(D15:D17) -> 5 | E18: =SUM(E15:E17) -> 31000 | F18: ='0422'!F18+'0423'!D18 -> 1397 | G18: ='0422'!G18+'0423'!E18 -> 7138000 | H18: ='0422'!H18+'0423'!D16 -> 106 | I18: ='0422'!I18+'0423'!D15 -> 708
B19: 비고 | C19: 단체 명 무료 명

Sheet 0424
A1: 기획전시 판매현황 | H1: 팀 장
H3: 46136
A4: 1 | B4: 전시명 : | C4: 섬냥이 in 장도 | F4: 전시일: | G4: 2026. 3. 27(금) ~ 6. 21(일)
H5: 목표 매출액: | I5: 10000000
B6: 판매현황 | C6: 구분 | D6: 판매매수 | E6: 금액 | F6: 점유율
C7: 유료 | D7: 45 | E7: 135000 | F7: =G10/I5 -> 0.2805
C8: 무료 | D8: 2
F9: 누계 총인원 | G9: 누계 총 금액 | H9: 누계 무료인원 | I9: 누계 유료인원
C10: 합계 | D10: =SUM(D7:D9) -> 47 | E10: =SUM(E7:E9) -> 135000 | F10: ='0423'!F10+'0424'!D10 -> 962 | G10: ='0423'!G10+'0424'!E10 -> 2805000 | H10: ='0423'!H10+'0424'!D8 -> 27 | I10: ='0423'!I10+'0424'!D7 -> 935
B11: 비고 | C11: 단체 20명 무료 2명
A12: 2 | B12: 전시명 : | C12: 어린이미술전 <우리 SUM 타볼래> | F12: 전시일: | G12: 2026. 2. 27(금) ~ 6. 28(일)
H13: 목표 매출액: | I13: 31500000
B14: 판매현황 | C14: 구분 | D14: 판매매수 | E14: 금액 | F14: 점유율
C15: 유료 | D15: 54 | E15: 314500 | F15: =G18/I13 -> 0.2365873
C16: 무료 | D16: 4
F17: 누계 총인원 | G17: 누계 총 금액 | H17: 누계 무료인원 | I17: 누계 유료인원
C18: 합계 | D18: =SUM(D15:D17) -> 58 | E18: =SUM(E15:E17) -> 314500 | F18: ='0423'!F18+'0424'!D18 -> 1455 | G18: ='0423'!G18+'0424'!E18 -> 7452500 | H18: ='0423'!H18+'0424'!D16 -> 110 | I18: ='0423'!I18+'0424'!D15 -> 762
B19: 비고 | C19: 단체 42명 무료 4명

Sheet 0425
A1: 기획전시 판매현황 | H1: 팀 장
H3: 46137
A4: 1 | B4: 전시명 : | C4: 섬냥이 in 장도 | F4: 전시일: | G4: 2026. 3. 27(금) ~ 6. 21(일)
H5: 목표 매출액: | I5: 10000000
B6: 판매현황 | C6: 구분 | D6: 판매매수 | E6: 금액 | F6: 점유율
C7: 유료 | D7: 56 | E7: 168000 | F7: =G10/I5 -> 0.2973
C8: 무료 | D8: 3
F9: 누계 총인원 | G9: 누계 총 금액 | H9: 누계 무료인원 | I9: 누계 유료인원
